Workbook

Sheet CourseProfile
A1: CLO-PLO Correlation
C2: C | D2: A | E2: P | F2: S
A3: CLO1
A4: CLO2
A5: CLO4 | B5: CLO Description | H5: Bloom’s Learning Levels | L5: PLO Assessed | M5: CLO-PLO Correlation
H6: C | I6: A | J6: P | K6: S
A7: CLO5
A8: CLO2
A9: CLO3
A10: CLO4
A11: CLO5
A12: CLO6

Sheet CT
A1: =CourseProfile!A1 -> CSE 2203+CSE 2204: Microprocessor and Microcontroller
A2: Allocated Marks for Class Tests
B3: CO mapping of Class Test Marks
B4: CT1 | E4: CT2 | H4: CT3
A5: CO No. | B5: Q1 | C5: Q2 | D5: Q3 | E5: Q1 | F5: Q2 | G5: Q3 | H5: Q1 | I5: Q2 | J5: Q3 | K5: CO Total | M5: CT Taken | Q5: =SUM(IF(D13>0,1,0),IF(G13>0,1,0),IF(J13>0,1,0)) -> 0
A6: CO1 | K6: =SUM(B6:J6) -> 0 | M6: CO Mapped CT Marks out of 60
A7: CO2 | K7: =SUM(B7:J7) -> 0 | M7: Use Eq. Wt for each CT | Q7: 0
A8: CO3 | K8: =SUM(B8:J8) -> 0
A9: CO4 | K9: =SUM(B9:J9) -> 0
A10: CO5 | K10: =SUM(B10:J10) -> 0 | X10: Don’t edit green/blue highlighted area
A11: CO6 | K11: =SUM(B11:J11) -> 0
A12: CT Total | B12: =SUM(B6:B10) -> 0 | C12: =SUM(C6:C10) -> 0 | D12: =SUM(D6:D10) -> 0 | E12: =SUM(E6:E10) -> 0 | F12: =SUM(F6:F10) -> 0 | G12: =SUM(G6:G10) -> 0 | H12: =SUM(H6:H10) -> 0 | I12: =SUM(I6:I10) -> 0 | J12: =SUM(J6:J10) -> 0 | K12: =SUM(K6:K11) -> 0
D13: =SUM(B12:D12) -> 0 | G13: =SUM(E12:G12) -> 0 | J13: =SUM(H12:J12) -> 0
A14: Factor | B14: =IFERROR(IF($Q$7,B15,B16)/D13,0) -> 0 | E14: =IFERROR(IF($Q$7,E15,E16)/G13,0) -> 0 | H14: =IFERROR(IF($Q$7,H15,H16)/J13,0) -> 0
A15: Eq. Wt | B15: =IF(D13,$Q$6/$Q$5,0) -> 0 | E15: =IF(G13,$Q$6/$Q$5,0) -> 0 | H15: =IF(J13,$Q$6/$Q$5,0) -> 0 | K15: =SUM(B15:J15) -> 0
A16: Manual Wt | K16: =SUM(B16:J16) -> 0 | L16: =IF(K16<>$Q$6,IF(Q7=0,"Sum should be "&$Q$6,"Sum should be "&$Q$6 &", you can ignore as Eq. wt=1"),"ok") -> ok
A18: CO No. | B18: =B3&" out of "&Q6 -> CO mapping of Class Test Marks out of | M18: CO No. | N18: ="CO wise multiplication factor out of " &Q6 -> CO wise multiplication factor out of
B19: =B4 -> CT1 | E19: =E4 -> CT2 | H19: =H4 -> CT3 | K19: CO Total | N19: =B4 -> CT1 | Q19: =E4 -> CT2 | T19: =H4 -> CT3
B20: =B5 -> Q1 | C20: =C5 -> Q2 | D20: =D5 -> Q3 | E20: =E5 -> Q1 | F20: =F5 -> Q2 | G20: =G5 -> Q3 | H20: =H5 -> Q1 | I20: =I5 -> Q2 | J20: =J5 -> Q3 | N20: =B5 -> Q1 | O20: =C5 -> Q2 | P20: =D5 -> Q3 | Q20: =E5 -> Q1 | R20: =F5 -> Q2 | S20: =G5 -> Q3 | T20: =H5 -> Q1 | U20: =I5 -> Q2 | V20: =J5 -> Q3
A21: CO1 | B21: =IFERROR(B6*$B$14,0) -> 0 | C21: =IFERROR(C6*$B$14,0) -> 0 | D21: =IFERROR(D6*$B$14,0) -> 0 | E21: =IFERROR(E6*$E$14,0) -> 0 | F21: =IFERROR(F6*$E$14,0) -> 0 | G21: =IFERROR(G6*$E$14,0) -> 0 | H21: =IFERROR(H6*$H$14,0) -> 0 | I21: =IFERROR(I6*$H$14,0) -> 0 | J21: =IFERROR(J6*$H$14,0) -> 0 | K21: =ROUND(SUM(B21:J21),2) -> 0 | M21: CO1 | N21: =IFERROR(B21/B6,0) -> 0 | O21: =IFERROR(C21/C6,0) -> 0 | P21: =IFERROR(D21/D6,0) -> 0 | Q21: =IFERROR(E21/E6,0) -> 0 | R21: =IFERROR(F21/F6,0) -> 0 | S21: =IFERROR(G21/G6,0) -> 0 | T21: =IFERROR(H21/H6,0) -> 0 | U21: =IFERROR(I21/I6,0) -> 0 | V21: =IFERROR(J21/J6,0) -> 0
A22: CO2 | B22: =IFERROR(B7*$B$14,0) -> 0 | C22: =IFERROR(C7*$B$14,0) -> 0 | D22: =IFERROR(D7*$B$14,0) -> 0 | E22: =IFERROR(E7*$E$14,0) -> 0 | F22: =IFERROR(F7*$E$14,0) -> 0 | G22: =IFERROR(G7*$E$14,0) -> 0 | H22: =IFERROR(H7*$H$14,0) -> 0 | I22: =IFERROR(I7*$H$14,0) -> 0 | J22: =IFERROR(J7*$H$14,0) -> 0 | K22: =ROUND(SUM(B22:J22),2) -> 0 | M22: CO2 | N22: =IFERROR(B22/B7,0) -> 0 | O22: =IFERROR(C22/C7,0) -> 0 | P22: =IFERROR(D22/D7,0) -> 0 | Q22: =IFERROR(E22/E7,0) -> 0 | R22: =IFERROR(F22/F7,0) -> 0 | S22: =IFERROR(G22/G7,0) -> 0 | T22: =IFERROR(H22/H7,0) -> 0 | U22: =IFERROR(I22/I7,0) -> 0 | V22: =IFERROR(J22/J7,0) -> 0
A23: CO3 | B23: =IFERROR(B8*$B$14,0) -> 0 | C23: =IFERROR(C8*$B$14,0) -> 0 | D23: =IFERROR(D8*$B$14,0) -> 0 | E23: =IFERROR(E8*$E$14,0) -> 0 | F23: =IFERROR(F8*$E$14,0) -> 0 | G23: =IFERROR(G8*$E$14,0) -> 0 | H23: =IFERROR(H8*$H$14,0) -> 0 | I23: =IFERROR(I8*$H$14,0) -> 0 | J23: =IFERROR(J8*$H$14,0) -> 0 | K23: =ROUND(SUM(B23:J23),2) -> 0 | M23: CO3 | N23: =IFERROR(B23/B8,0) -> 0 | O23: =IFERROR(C23/C8,0) -> 0 | P23: =IFERROR(D23/D8,0) -> 0 | Q23: =IFERROR(E23/E8,0) -> 0 | R23: =IFERROR(F23/F8,0) -> 0 | S23: =IFERROR(G23/G8,0) -> 0 | T23: =IFERROR(H23/H8,0) -> 0 | U23: =IFERROR(I23/I8,0) -> 0 | V23: =IFERROR(J23/J8,0) -> 0
A24: CO4 | B24: =IFERROR(B9*$B$14,0) -> 0 | C24: =IFERROR(C9*$B$14,0) -> 0 | D24: =IFERROR(D9*$B$14,0) -> 0 | E24: =IFERROR(E9*$E$14,0) -> 0 | F24: =IFERROR(F9*$E$14,0) -> 0 | G24: =IFERROR(G9*$E$14,0) -> 0 | H24: =IFERROR(H9*$H$14,0) -> 0 | I24: =IFERROR(I9*$H$14,0) -> 0 | J24: =IFERROR(J9*$H$14,0) -> 0 | K24: =ROUND(SUM(B24:J24),2) -> 0 | M24: CO4 | N24: =IFERROR(B24/B9,0) -> 0 | O24: =IFERROR(C24/C9,0) -> 0 | P24: =IFERROR(D24/D9,0) -> 0 | Q24: =IFERROR(E24/E9,0) -> 0 | R24: =IFERROR(F24/F9,0) -> 0 | S24: =IFERROR(G24/G9,0) -> 0 | T24: =IFERROR(H24/H9,0) -> 0 | U24: =IFERROR(I24/I9,0) -> 0 | V24: =IFERROR(J24/J9,0) -> 0
A25: CO5 | B25: =IFERROR(B10*$B$14,0) -> 0 | C25: =IFERROR(C10*$B$14,0) -> 0 | D25: =IFERROR(D10*$B$14,0) -> 0 | E25: =IFERROR(E10*$E$14,0) -> 0 | F25: =IFERROR(F10*$E$14,0) -> 0 | G25: =IFERROR(G10*$E$14,0) -> 0 | H25: =IFERROR(H10*$H$14,0) -> 0 | I25: =IFERROR(I10*$H$14,0) -> 0 | J25: =IFERROR(J10*$H$14,0) -> 0 | K25: =ROUND(SUM(B25:J25),2) -> 0 | M25: CO5 | N25: =IFERROR(B25/B10,0) -> 0 | O25: =IFERROR(C25/C10,0) -> 0 | P25: =IFERROR(D25/D10,0) -> 0 | Q25: =IFERROR(E25/E10,0) -> 0 | R25: =IFERROR(F25/F10,0) -> 0 | S25: =IFERROR(G25/G10,0) -> 0 | T25: =IFERROR(H25/H10,0) -> 0 | U25: =IFERROR(I25/I10,0) -> 0 | V25: =IFERROR(J25/J10,0) -> 0
A26: CO6 | B26: =IFERROR(B11*$B$14,0) -> 0 | C26: =IFERROR(C11*$B$14,0) -> 0 | D26: =IFERROR(D11*$B$14,0) -> 0 | E26: =IFERROR(E11*$E$14,0) -> 0 | F26: =IFERROR(F11*$E$14,0) -> 0 | G26: =IFERROR(G11*$E$14,0) -> 0 | H26: =IFERROR(H11*$H$14,0) -> 0 | I26: =IFERROR(I11*$H$14,0) -> 0 | J26: =IFERROR(J11*$H$14,0) -> 0 | K26: =ROUND(SUM(B26:J26),2) -> 0 | M26: CO6 | N26: =IFERROR(B26/B11,0) -> 0 | O26: =IFERROR(C26/C11,0) -> 0 | P26: =IFERROR(D26/D11,0) -> 0 | Q26: =IFERROR(E26/E11,0) -> 0 | R26: =IFERROR(F26/F11,0) -> 0 | S26: =IFERROR(G26/G11,0) -> 0 | T26: =IFERROR(H26/H11,0) -> 0 | U26: =IFERROR(I26/I11,0) -> 0 | V26: =IFERROR(J26/J11,0) -> 0
K27: =SUM(K21:K26) -> 0 | L27: =IF(K27<>$Q$6,"Should be "&$Q$6,"ok") -> ok
A28: Obtained Marks for Class Tests | M28: =IF(K27<>Q6,"CT marks mismatch, check "&ADDRESS(ROW(K27),COLUMN(K27),4)&"and manual wt sum","CT marks okay") -> CT marks okay
A29: Roll | B29: ="Class Test marks obtained out of "&K12 -> Class Test marks obtained out of 0 | M29: ="CO wise obtained marks out of " &K12 -> CO wise obtained marks out of 0 | T29: ="CO wise obtained marks out of " &K27 -> CO wise obtained marks out of 0
B30: =B4&" ("&D13 &")" -> CT1 (0) | E30: =E4&" ("&G13 &")" -> CT2 (0) | H30: =H4&" ("&J13 &")" -> CT3 (0) | K30: ="Total ("&K12&")" -> Total (0) | M30: CO1 | N30: CO2 | O30: CO3 | P30: CO4 | Q30: CO5 | R30: CO6 | T30: CO1 | U30: CO2 | V30: CO3 | W30: CO4 | X30: CO5 | Y30: CO6
B31: =B20 -> Q1 | C31: =C20 -> Q2 | D31: =D20 -> Q3 | E31: =E20 -> Q1 | F31: =F20 -> Q2 | G31: =G20 -> Q3 | H31: =H20 -> Q1 | I31: =I20 -> Q2 | J31: =J20 -> Q3 | M31: ="("&K6&")" -> (0) | N31: ="("&K7&")" -> (0) | O31: ="("&K8&")" -> (0) | P31: ="("&K9&")" -> (0) | Q31: ="("&K10&")" -> (0) | R31: ="("&K11&")" -> (0) | T31: ="("&K21&")" -> (0) | U31: ="("&K22&")" -> (0) | V31: ="("&K23&")" -> (0) | W31: ="("&K24&")" -> (0) | X31: ="("&K25&")" -> (0) | Y31: ="("&K26&")" -> (0)
K32: =SUM(B32:J32) -> 0 | M32: =IF(ISBLANK($A32),"",SUMIF($B$6:$J$6,">0",$B32:$J32)) | N32: =IF(ISBLANK($A32),"",SUMIF($B$7:$J$7,">0",$B32:$J32)) | O32: =IF(ISBLANK($A32),"",SUMIF($B$8:$J$8,">0",$B32:$J32)) | P32: =IF(ISBLANK($A32),"",SUMIF($B$9:$J$9,">0",$B32:$J32)) | Q32: =IF(ISBLANK($A32),"",SUMIF($B$10:$J$10,">0",$B32:$J32)) | R32: =IF(ISBLANK($A32),"",SUMIF($B$11:$J$11,">0",$B32:$J32)) | T32: =IF(ISBLANK($A32),"",SUMPRODUCT($B32:$J32,$N$21:$V$21)) | U32: =IF(ISBLANK($A32),"",SUMPRODUCT($B32:$J32,$N$22:$V$22)) | V32: =IF(ISBLANK($A32),"",SUMPRODUCT($B32:$J32,$N$23:$V$23)) | W32: =IF(ISBLANK($A32),"",SUMPRODUCT($B32:$J32,$N$24:$V$24)) | X32: =IF(ISBLANK($A32),"",SUMPRODUCT($B32:$J32,$N$25:$V$25)) | Y32: =IF(ISBLANK($A32),"",SUMPRODUCT($B32:$J32,$N$26:$V$26))
K33: =SUM(B33:J33) -> 0 | M33: =IF(ISBLANK($A33),"",SUMIF($B$6:$J$6,">0",$B33:$J33)) | N33: =IF(ISBLANK($A33),"",SUMIF($B$7:$J$7,">0",$B33:$J33)) | O33: =IF(ISBLANK($A33),"",SUMIF($B$8:$J$8,">0",$B33:$J33)) | P33: =IF(ISBLANK($A33),"",SUMIF($B$9:$J$9,">0",$B33:$J33)) | Q33: =IF(ISBLANK($A33),"",SUMIF($B$10:$J$10,">0",$B33:$J33)) | R33: =IF(ISBLANK($A33),"",SUMIF($B$11:$J$11,">0",$B33:$J33)) | T33: =IF(ISBLANK($A33),"",SUMPRODUCT($B33:$J33,$N$21:$V$21)) | U33: =IF(ISBLANK($A33),"",SUMPRODUCT($B33:$J33,$N$22:$V$22)) | V33: =IF(ISBLANK($A33),"",SUMPRODUCT($B33:$J33,$N$23:$V$23)) | W33: =IF(ISBLANK($A33),"",SUMPRODUCT($B33:$J33,$N$24:$V$24)) | X33: =IF(ISBLANK($A33),"",SUMPRODUCT($B33:$J33,$N$25:$V$25)) | Y33: =IF(ISBLANK($A33),"",SUMPRODUCT($B33:$J33,$N$26:$V$26))
K34: =SUM(B34:J34) -> 0 | M34: =IF(ISBLANK($A34),"",SUMIF($B$6:$J$6,">0",$B34:$J34)) | N34: =IF(ISBLANK($A34),"",SUMIF($B$7:$J$7,">0",$B34:$J34)) | O34: =IF(ISBLANK($A34),"",SUMIF($B$8:$J$8,">0",$B34:$J34)) | P34: =IF(ISBLANK($A34),"",SUMIF($B$9:$J$9,">0",$B34:$J34)) | Q34: =IF(ISBLANK($A34),"",SUMIF($B$10:$J$10,">0",$B34:$J34)) | R34: =IF(ISBLANK($A34),"",SUMIF($B$11:$J$11,">0",$B34:$J34)) | T34: =IF(ISBLANK($A34),"",SUMPRODUCT($B34:$J34,$N$21:$V$21)) | U34: =IF(ISBLANK($A34),"",SUMPRODUCT($B34:$J34,$N$22:$V$22)) | V34: =IF(ISBLANK($A34),"",SUMPRODUCT($B34:$J34,$N$23:$V$23)) | W34: =IF(ISBLANK($A34),"",SUMPRODUCT($B34:$J34,$N$24:$V$24)) | X34: =IF(ISBLANK($A34),"",SUMPRODUCT($B34:$J34,$N$25:$V$25)) | Y34: =IF(ISBLANK($A34),"",SUMPRODUCT($B34:$J34,$N$26:$V$26))
K35: =SUM(B35:J35) -> 0 | M35: =IF(ISBLANK($A35),"",SUMIF($B$6:$J$6,">0",$B35:$J35)) | N35: =IF(ISBLANK($A35),"",SUMIF($B$7:$J$7,">0",$B35:$J35)) | O35: =IF(ISBLANK($A35),"",SUMIF($B$8:$J$8,">0",$B35:$J35)) | P35: =IF(ISBLANK($A35),"",SUMIF($B$9:$J$9,">0",$B35:$J35)) | Q35: =IF(ISBLANK($A35),"",SUMIF($B$10:$J$10,">0",$B35:$J35)) | R35: =IF(ISBLANK($A35),"",SUMIF($B$11:$J$11,">0",$B35:$J35)) | T35: =IF(ISBLANK($A35),"",SUMPRODUCT($B35:$J35,$N$21:$V$21)) | U35: =IF(ISBLANK($A35),"",SUMPRODUCT($B35:$J35,$N$22:$V$22)) | V35: =IF(ISBLANK($A35),"",SUMPRODUCT($B35:$J35,$N$23:$V$23)) | W35: =IF(ISBLANK($A35),"",SUMPRODUCT($B35:$J35,$N$24:$V$24)) | X35: =IF(ISBLANK($A35),"",SUMPRODUCT($B35:$J35,$N$25:$V$25)) | Y35: =IF(ISBLANK($A35),"",SUMPRODUCT($B35:$J35,$N$26:$V$26))
K36: =SUM(B36:J36) -> 0 | M36: =IF(ISBLANK($A36),"",SUMIF($B$6:$J$6,">0",$B36:$J36)) | N36: =IF(ISBLANK($A36),"",SUMIF($B$7:$J$7,">0",$B36:$J36)) | O36: =IF(ISBLANK($A36),"",SUMIF($B$8:$J$8,">0",$B36:$J36)) | P36: =IF(ISBLANK($A36),"",SUMIF($B$9:$J$9,">0",$B36:$J36)) | Q36: =IF(ISBLANK($A36),"",SUMIF($B$10:$J$10,">0",$B36:$J36)) | R36: =IF(ISBLANK($A36),"",SUMIF($B$11:$J$11,">0",$B36:$J36)) | T36: =IF(ISBLANK($A36),"",SUMPRODUCT($B36:$J36,$N$21:$V$21)) | U36: =IF(ISBLANK($A36),"",SUMPRODUCT($B36:$J36,$N$22:$V$22)) | V36: =IF(ISBLANK($A36),"",SUMPRODUCT($B36:$J36,$N$23:$V$23)) | W36: =IF(ISBLANK($A36),"",SUMPRODUCT($B36:$J36,$N$24:$V$24)) | X36: =IF(ISBLANK($A36),"",SUMPRODUCT($B36:$J36,$N$25:$V$25)) | Y36: =IF(ISBLANK($A36),"",SUMPRODUCT($B36:$J36,$N$26:$V$26))
K37: =SUM(B37:J37) -> 0 | M37: =IF(ISBLANK($A37),"",SUMIF($B$6:$J$6,">0",$B37:$J37)) | N37: =IF(ISBLANK($A37),"",SUMIF($B$7:$J$7,">0",$B37:$J37)) | O37: =IF(ISBLANK($A37),"",SUMIF($B$8:$J$8,">0",$B37:$J37)) | P37: =IF(ISBLANK($A37),"",SUMIF($B$9:$J$9,">0",$B37:$J37)) | Q37: =IF(ISBLANK($A37),"",SUMIF($B$10:$J$10,">0",$B37:$J37)) | R37: =IF(ISBLANK($A37),"",SUMIF($B$11:$J$11,">0",$B37:$J37)) | T37: =IF(ISBLANK($A37),"",SUMPRODUCT($B37:$J37,$N$21:$V$21)) | U37: =IF(ISBLANK($A37),"",SUMPRODUCT($B37:$J37,$N$22:$V$22)) | V37: =IF(ISBLANK($A37),"",SUMPRODUCT($B37:$J37,$N$23:$V$23)) | W37: =IF(ISBLANK($A37),"",SUMPRODUCT($B37:$J37,$N$24:$V$24)) | X37: =IF(ISBLANK($A37),"",SUMPRODUCT($B37:$J37,$N$25:$V$25)) | Y37: =IF(ISBLANK($A37),"",SUMPRODUCT($B37:$J37,$N$26:$V$26))
K38: =SUM(B38:J38) -> 0 | M38: =IF(ISBLANK($A38),"",SUMIF($B$6:$J$6,">0",$B38:$J38)) | N38: =IF(ISBLANK($A38),"",SUMIF($B$7:$J$7,">0",$B38:$J38)) | O38: =IF(ISBLANK($A38),"",SUMIF($B$8:$J$8,">0",$B38:$J38)) | P38: =IF(ISBLANK($A38),"",SUMIF($B$9:$J$9,">0",$B38:$J38)) | Q38: =IF(ISBLANK($A38),"",SUMIF($B$10:$J$10,">0",$B38:$J38)) | R38: =IF(ISBLANK($A38),"",SUMIF($B$11:$J$11,">0",$B38:$J38)) | T38: =IF(ISBLANK($A38),"",SUMPRODUCT($B38:$J38,$N$21:$V$21)) | U38: =IF(ISBLANK($A38),"",SUMPRODUCT($B38:$J38,$N$22:$V$22)) | V38: =IF(ISBLANK($A38),"",SUMPRODUCT($B38:$J38,$N$23:$V$23)) | W38: =IF(ISBLANK($A38),"",SUMPRODUCT($B38:$J38,$N$24:$V$24)) | X38: =IF(ISBLANK($A38),"",SUMPRODUCT($B38:$J38,$N$25:$V$25)) | Y38: =IF(ISBLANK($A38),"",SUMPRODUCT($B38:$J38,$N$26:$V$26))
K39: =SUM(B39:J39) -> 0 | M39: =IF(ISBLANK($A39),"",SUMIF($B$6:$J$6,">0",$B39:$J39)) | N39: =IF(ISBLANK($A39),"",SUMIF($B$7:$J$7,">0",$B39:$J39)) | O39: =IF(ISBLANK($A39),"",SUMIF($B$8:$J$8,">0",$B39:$J39)) | P39: =IF(ISBLANK($A39),"",SUMIF($B$9:$J$9,">0",$B39:$J39)) | Q39: =IF(ISBLANK($A39),"",SUMIF($B$10:$J$10,">0",$B39:$J39)) | R39: =IF(ISBLANK($A39),"",SUMIF($B$11:$J$11,">0",$B39:$J39)) | T39: =IF(ISBLANK($A39),"",SUMPRODUCT($B39:$J39,$N$21:$V$21)) | U39: =IF(ISBLANK($A39),"",SUMPRODUCT($B39:$J39,$N$22:$V$22)) | V39: =IF(ISBLANK($A39),"",SUMPRODUCT($B39:$J39,$N$23:$V$23)) | W39: =IF(ISBLANK($A39),"",SUMPRODUCT($B39:$J39,$N$24:$V$24)) | X39: =IF(ISBLANK($A39),"",SUMPRODUCT($B39:$J39,$N$25:$V$25)) | Y39: =IF(ISBLANK($A39),"",SUMPRODUCT($B39:$J39,$N$26:$V$26))
K40: =SUM(B40:J40) -> 0 | M40: =IF(ISBLANK($A40),"",SUMIF($B$6:$J$6,">0",$B40:$J40)) | N40: =IF(ISBLANK($A40),"",SUMIF($B$7:$J$7,">0",$B40:$J40)) | O40: =IF(ISBLANK($A40),"",SUMIF($B$8:$J$8,">0",$B40:$J40)) | P40: =IF(ISBLANK($A40),"",SUMIF($B$9:$J$9,">0",$B40:$J40)) | Q40: =IF(ISBLANK($A40),"",SUMIF($B$10:$J$10,">0",$B40:$J40)) | R40: =IF(ISBLANK($A40),"",SUMIF($B$11:$J$11,">0",$B40:$J40)) | T40: =IF(ISBLANK($A40),"",SUMPRODUCT($B40:$J40,$N$21:$V$21)) | U40: =IF(ISBLANK($A40),"",SUMPRODUCT($B40:$J40,$N$22:$V$22)) | V40: =IF(ISBLANK($A40),"",SUMPRODUCT($B40:$J40,$N$23:$V$23)) | W40: =IF(ISBLANK($A40),"",SUMPRODUCT($B40:$J40,$N$24:$V$24)) | X40: =IF(ISBLANK($A40),"",SUMPRODUCT($B40:$J40,$N$25:$V$25)) | Y40: =IF(ISBLANK($A40),"",SUMPRODUCT($B40:$J40,$N$26:$V$26))
K41: =SUM(B41:J41) -> 0 | M41: =IF(ISBLANK($A41),"",SUMIF($B$6:$J$6,">0",$B41:$J41)) | N41: =IF(ISBLANK($A41),"",SUMIF($B$7:$J$7,">0",$B41:$J41)) | O41: =IF(ISBLANK($A41),"",SUMIF($B$8:$J$8,">0",$B41:$J41)) | P41: =IF(ISBLANK($A41),"",SUMIF($B$9:$J$9,">0",$B41:$J41)) | Q41: =IF(ISBLANK($A41),"",SUMIF($B$10:$J$10,">0",$B41:$J41)) | R41: =IF(ISBLANK($A41),"",SUMIF($B$11:$J$11,">0",$B41:$J41)) | T41: =IF(ISBLANK($A41),"",SUMPRODUCT($B41:$J41,$N$21:$V$21)) | U41: =IF(ISBLANK($A41),"",SUMPRODUCT($B41:$J41,$N$22:$V$22)) | V41: =IF(ISBLANK($A41),"",SUMPRODUCT($B41:$J41,$N$23:$V$23)) | W41: =IF(ISBLANK($A41),"",SUMPRODUCT($B41:$J41,$N$24:$V$24)) | X41: =IF(ISBLANK($A41),"",SUMPRODUCT($B41:$J41,$N$25:$V$25)) | Y41: =IF(ISBLANK($A41),"",SUMPRODUCT($B41:$J41,$N$26:$V$26))
...

Sheet Attn_Assign
A1: =CT!A1 -> CSE 2203+CSE 2204: Microprocessor and Microcontroller
A2: Allocated Marks for Attendance and Assignment (if taken)
B3: Attn. Perf. | C3: CO mapping of Assingment Marks | T3: Don’t edit green/blue highlighted area
C4: Assignment1 | F4: Assignment2 | I4: Assignment3
A5: CO No. | C5: Q1 | D5: Q2 | E5: Q3 | F5: Q1 | G5: Q2 | H5: Q3 | I5: Q1 | J5: Q2 | K5: Q3 | L5: CO Total | N5: Assign. Taken | R5: =SUM(IF(H13>0,1,0),IF(K13>0,1,0),IF(E13>0,1,0)) -> 0
A6: CO1 | B6: … | L6: =SUM(C6:K6) -> 0 | N6: Assignmnt Marks out of 30
A7: CO2 | B7: … | L7: =SUM(C7:K7) -> 0 | N7: Use Eq. Wt | R7: 0
A8: CO3 | B8: … | L8: =SUM(C8:K8) -> 0
A9: CO4 | B9: … | L9: =SUM(C9:K9) -> 0
A10: CO5 | B10: … | L10: =SUM(C10:K10) -> 0
A11: CO6 | B11: … | L11: =SUM(C11:K11) -> 0
A12: Assign Total | C12: =SUM(C6:C10) -> 0 | D12: =SUM(D6:D10) -> 0 | E12: =SUM(E6:E10) -> 0 | F12: =SUM(F6:F10) -> 0 | G12: =SUM(G6:G10) -> 0 | H12: =SUM(H6:H10) -> 0 | I12: =SUM(I6:I10) -> 0 | J12: =SUM(J6:J10) -> 0 | K12: =SUM(K6:K10) -> 0 | L12: =SUM(L6:L11) -> 0
E13: =SUM(C12:E12) -> 0 | H13: =SUM(F12:H12) -> 0 | K13: =SUM(I12:K12) -> 0
A14: Factor | C14: =IFERROR(IF($R$7,C15,C16)/E13,0) -> 0 | F14: =IFERROR(IF($R$7,F15,F16)/H13,0) -> 0 | I14: =IFERROR(IF($R$7,I15,I16)/K13,0) -> 0
A15: Eq. Wt | C15: =IF(E13,$R$6/$R$5,0) -> 0 | F15: =IF(H13,$R$6/$R$5,0) -> 0 | I15: =IF(K13,$R$6/$R$5,0) -> 0 | L15: =SUM(C15:K15) -> 0
A16: Manual Wt | L16: =SUM(C16:K16) -> 0 | M16: =IF(L16<>$R$6,IF(R7=0,"Sum should be "&$R$6,"Sum should be "&$R$6 &", you can ignore as Eq. wt=1"),"ok") -> ok
A18: CO No. | B18: =B3 -> Attn. Perf. | C18: =C3&" out of "&R6 -> CO mapping of Assingment Marks out of | L18: CO Total | N18: CO No. | O18: ="CO wise multiplication factor out of " &R6 -> CO wise multiplication factor out of
C19: =C4 -> Assignment1 | F19: =F4 -> Assignment2 | I19: =I4 -> Assignment3 | O19: =C4 -> Assignment1 | R19: =F4 -> Assignment2 | U19: =I4 -> Assignment3
C20: =C5 -> Q1 | D20: =D5 -> Q2 | E20: =E5 -> Q3 | F20: =F5 -> Q1 | G20: =G5 -> Q2 | H20: =H5 -> Q3 | I20: =I5 -> Q1 | J20: =J5 -> Q2 | K20: =K5 -> Q3 | O20: Q1 | P20: Q2 | Q20: Total | R20: Q1 | S20: Q2 | T20: Total | U20: Q1 | V20: Q2 | W20: Total
A21: CO1 | C21: =IFERROR(C6*$C$14,0) -> 0 | D21: =IFERROR(D6*$C$14,0) -> 0 | E21: =IFERROR(E6*$C$14,0) -> 0 | F21: =IFERROR(F6*$F$14,0) -> 0 | G21: =IFERROR(G6*$F$14,0) -> 0 | H21: =IFERROR(H6*$F$14,0) -> 0 | I21: =IFERROR(I6*$I$14,0) -> 0 | J21: =IFERROR(J6*$I$14,0) -> 0 | K21: =IFERROR(K6*$I$14,0) -> 0 | L21: =ROUND(SUM(C21:K21),2) -> 0 | N21: CO1 | O21: =IFERROR(C21/C6,0) -> 0 | P21: =IFERROR(D21/D6,0) -> 0 | Q21: =IFERROR(E21/E6,0) -> 0 | R21: =IFERROR(F21/F6,0) -> 0 | S21: =IFERROR(G21/G6,0) -> 0 | T21: =IFERROR(H21/H6,0) -> 0 | U21: =IFERROR(I21/I6,0) -> 0 | V21: =IFERROR(J21/J6,0) -> 0 | W21: =IFERROR(K21/K6,0) -> 0
A22: CO2 | C22: =IFERROR(C7*$C$14,0) -> 0 | D22: =IFERROR(D7*$C$14,0) -> 0 | E22: =IFERROR(E7*$C$14,0) -> 0 | F22: =IFERROR(F7*$F$14,0) -> 0 | G22: =IFERROR(G7*$F$14,0) -> 0 | H22: =IFERROR(H7*$F$14,0) -> 0 | I22: =IFERROR(I7*$I$14,0) -> 0 | J22: =IFERROR(J7*$I$14,0) -> 0 | K22: =IFERROR(K7*$I$14,0) -> 0 | L22: =ROUND(SUM(C22:K22),2) -> 0 | N22: CO2 | O22: =IFERROR(C22/C7,0) -> 0 | P22: =IFERROR(D22/D7,0) -> 0 | Q22: =IFERROR(E22/E7,0) -> 0 | R22: =IFERROR(F22/F7,0) -> 0 | S22: =IFERROR(G22/G7,0) -> 0 | T22: =IFERROR(H22/H7,0) -> 0 | U22: =IFERROR(I22/I7,0) -> 0 | V22: =IFERROR(J22/J7,0) -> 0 | W22: =IFERROR(K22/K7,0) -> 0
A23: CO3 | C23: =IFERROR(C8*$C$14,0) -> 0 | D23: =IFERROR(D8*$C$14,0) -> 0 | E23: =IFERROR(E8*$C$14,0) -> 0 | F23: =IFERROR(F8*$F$14,0) -> 0 | G23: =IFERROR(G8*$F$14,0) -> 0 | H23: =IFERROR(H8*$F$14,0) -> 0 | I23: =IFERROR(I8*$I$14,0) -> 0 | J23: =IFERROR(J8*$I$14,0) -> 0 | K23: =IFERROR(K8*$I$14,0) -> 0 | L23: =ROUND(SUM(C23:K23),2) -> 0 | N23: CO3 | O23: =IFERROR(C23/C8,0) -> 0 | P23: =IFERROR(D23/D8,0) -> 0 | Q23: =IFERROR(E23/E8,0) -> 0 | R23: =IFERROR(F23/F8,0) -> 0 | S23: =IFERROR(G23/G8,0) -> 0 | T23: =IFERROR(H23/H8,0) -> 0 | U23: =IFERROR(I23/I8,0) -> 0 | V23: =IFERROR(J23/J8,0) -> 0 | W23: =IFERROR(K23/K8,0) -> 0
A24: CO4 | C24: =IFERROR(C9*$C$14,0) -> 0 | D24: =IFERROR(D9*$C$14,0) -> 0 | E24: =IFERROR(E9*$C$14,0) -> 0 | F24: =IFERROR(F9*$F$14,0) -> 0 | G24: =IFERROR(G9*$F$14,0) -> 0 | H24: =IFERROR(H9*$F$14,0) -> 0 | I24: =IFERROR(I9*$I$14,0) -> 0 | J24: =IFERROR(J9*$I$14,0) -> 0 | K24: =IFERROR(K9*$I$14,0) -> 0 | L24: =ROUND(SUM(C24:K24),2) -> 0 | N24: CO4 | O24: =IFERROR(C24/C9,0) -> 0 | P24: =IFERROR(D24/D9,0) -> 0 | Q24: =IFERROR(E24/E9,0) -> 0 | R24: =IFERROR(F24/F9,0) -> 0 | S24: =IFERROR(G24/G9,0) -> 0 | T24: =IFERROR(H24/H9,0) -> 0 | U24: =IFERROR(I24/I9,0) -> 0 | V24: =IFERROR(J24/J9,0) -> 0 | W24: =IFERROR(K24/K9,0) -> 0
A25: CO5 | C25: =IFERROR(C10*$C$14,0) -> 0 | D25: =IFERROR(D10*$C$14,0) -> 0 | E25: =IFERROR(E10*$C$14,0) -> 0 | F25: =IFERROR(F10*$F$14,0) -> 0 | G25: =IFERROR(G10*$F$14,0) -> 0 | H25: =IFERROR(H10*$F$14,0) -> 0 | I25: =IFERROR(I10*$I$14,0) -> 0 | J25: =IFERROR(J10*$I$14,0) -> 0 | K25: =IFERROR(K10*$I$14,0) -> 0 | L25: =ROUND(SUM(C25:K25),2) -> 0 | N25: CO5 | O25: =IFERROR(C25/C10,0) -> 0 | P25: =IFERROR(D25/D10,0) -> 0 | Q25: =IFERROR(E25/E10,0) -> 0 | R25: =IFERROR(F25/F10,0) -> 0 | S25: =IFERROR(G25/G10,0) -> 0 | T25: =IFERROR(H25/H10,0) -> 0 | U25: =IFERROR(I25/I10,0) -> 0 | V25: =IFERROR(J25/J10,0) -> 0 | W25: =IFERROR(K25/K10,0) -> 0
A26: CO6 | C26: =IFERROR(C11*$C$14,0) -> 0 | D26: =IFERROR(D11*$C$14,0) -> 0 | E26: =IFERROR(E11*$C$14,0) -> 0 | F26: =IFERROR(F11*$F$14,0) -> 0 | G26: =IFERROR(G11*$F$14,0) -> 0 | H26: =IFERROR(H11*$F$14,0) -> 0 | I26: =IFERROR(I11*$I$14,0) -> 0 | J26: =IFERROR(J11*$I$14,0) -> 0 | K26: =IFERROR(K11*$I$14,0) -> 0 | L26: =ROUND(SUM(C26:K26),2) -> 0 | N26: CO6 | O26: =IFERROR(C26/C11,0) -> 0 | P26: =IFERROR(D26/D11,0) -> 0 | Q26: =IFERROR(E26/E11,0) -> 0 | R26: =IFERROR(F26/F11,0) -> 0 | S26: =IFERROR(G26/G11,0) -> 0 | T26: =IFERROR(H26/H11,0) -> 0 | U26: =IFERROR(I26/I11,0) -> 0 | V26: =IFERROR(J26/J11,0) -> 0 | W26: =IFERROR(K26/K11,0) -> 0
L27: =SUM(L21:L26) -> 0 | M27: =IF(L27<>$R$6,"Should be "&$R$6,"ok") -> ok
A28: Obtained Marks for Attendance, Performance and Assignment | N28: =IF(SUM(B5,L27)<>30,"Att+Assignment marks mismatch, check "&ADDRESS(ROW(B5),COLUMN(B5),4)&"+"&ADDRESS(ROW(L27),COLUMN(L27),4),"Att+Assignment marks okay") -> Att+Assignment marks mismatch, check B5+L27
A29: Roll | B29: =B3 -> Attn. Perf. | C29: ="Assignment marks obtained out of "&L12 -> Assignment marks obtained out of 0 | N29: ="CO wise obtained marks out of " &L12 -> CO wise obtained marks out of 0 | U29: ="CO wise obtained marks out of " &L27 -> CO wise obtained marks out of 0
C30: =C4&" ("&E13 &")" -> Assignment1 (0) | F30: =F4&" ("&H13 &")" -> Assignment2 (0) | I30: =I4&" ("&K13 &")" -> Assignment3 (0) | L30: ="Total ("&L12&")" -> Total (0) | N30: CO1 | O30: CO2 | P30: CO3 | Q30: CO4 | R30: CO5 | S30: CO6 | U30: CO1 | V30: CO2 | W30: CO3 | X30: CO4 | Y30: CO5 | Z30: CO6
B31: ="Out of "&B5 -> Out of | C31: =C5 -> Q1 | D31: =D5 -> Q2 | E31: =E5 -> Q3 | F31: =F5 -> Q1 | G31: =G5 -> Q2 | H31: =H5 -> Q3 | I31: =I5 -> Q1 | J31: =J5 -> Q2 | K31: =K5 -> Q3 | N31: ="("&L6&")" -> (0) | O31: ="("&L7&")" -> (0) | P31: ="("&L8&")" -> (0) | Q31: ="("&L9&")" -> (0) | R31: ="("&L10&")" -> (0) | S31: ="("&L11&")" -> (0) | U31: ="("&L21&")" -> (0) | V31: ="("&L22&")" -> (0) | W31: ="("&L23&")" -> (0) | X31: ="("&L24&")" -> (0) | Y31: ="("&L25&")" -> (0) | Z31: ="("&L26&")" -> (0)
A32: =IF(ISBLANK(CT!A32),"",CT!A32) | L32: =SUM(C32:K32) -> 0 | N32: =IF($A32="","",SUMIF($C$6:$K$6,">0",$C32:$K32)) | O32: =IF($A32="","",SUMIF($C$7:$K$7,">0",$C32:$K32)) | P32: =IF($A32="","",SUMIF($C$8:$K$8,">0",$C32:$K32)) | Q32: =IF($A32="","",SUMIF($C$9:$K$9,">0",$C32:$K32)) | R32: =IF($A32="","",SUMIF($C$10:$K$10,">0",$C32:$K32)) | S32: =IF($A32="","",SUMIF($C$11:$K$11,">0",$C32:$K32)) | U32: =IF($A32="","",SUMPRODUCT($C32:$K32,$O$21:$W$21)) | V32: =IF($A32="","",SUMPRODUCT($C32:$K32,$O$22:$W$22)) | W32: =IF($A32="","",SUMPRODUCT($C32:$K32,$O$23:$W$23)) | X32: =IF($A32="","",SUMPRODUCT($C32:$K32,$O$24:$W$24)) | Y32: =IF($A32="","",SUMPRODUCT($C32:$K32,$O$25:$W$25)) | Z32: =IF($A32="","",SUMPRODUCT($C32:$K32,$O$26:$W$26))
A33: =IF(ISBLANK(CT!A33),"",CT!A33) | L33: =SUM(C33:K33) -> 0 | N33: =IF($A33="","",SUMIF($C$6:$K$6,">0",$C33:$K33)) | O33: =IF($A33="","",SUMIF($C$7:$K$7,">0",$C33:$K33)) | P33: =IF($A33="","",SUMIF($C$8:$K$8,">0",$C33:$K33)) | Q33: =IF($A33="","",SUMIF($C$9:$K$9,">0",$C33:$K33)) | R33: =IF($A33="","",SUMIF($C$10:$K$10,">0",$C33:$K33)) | S33: =IF($A33="","",SUMIF($C$11:$K$11,">0",$C33:$K33)) | U33: =IF($A33="","",SUMPRODUCT($C33:$K33,$O$21:$W$21)) | V33: =IF($A33="","",SUMPRODUCT($C33:$K33,$O$22:$W$22)) | W33: =IF($A33="","",SUMPRODUCT($C33:$K33,$O$23:$W$23)) | X33: =IF($A33="","",SUMPRODUCT($C33:$K33,$O$24:$W$24)) | Y33: =IF($A33="","",SUMPRODUCT($C33:$K33,$O$25:$W$25)) | Z33: =IF($A33="","",SUMPRODUCT($C33:$K33,$O$26:$W$26))
A34: =IF(ISBLANK(CT!A34),"",CT!A34) | L34: =SUM(C34:K34) -> 0 | N34: =IF($A34="","",SUMIF($C$6:$K$6,">0",$C34:$K34)) | O34: =IF($A34="","",SUMIF($C$7:$K$7,">0",$C34:$K34)) | P34: =IF($A34="","",SUMIF($C$8:$K$8,">0",$C34:$K34)) | Q34: =IF($A34="","",SUMIF($C$9:$K$9,">0",$C34:$K34)) | R34: =IF($A34="","",SUMIF($C$10:$K$10,">0",$C34:$K34)) | S34: =IF($A34="","",SUMIF($C$11:$K$11,">0",$C34:$K34)) | U34: =IF($A34="","",SUMPRODUCT($C34:$K34,$O$21:$W$21)) | V34: =IF($A34="","",SUMPRODUCT($C34:$K34,$O$22:$W$22)) | W34: =IF($A34="","",SUMPRODUCT($C34:$K34,$O$23:$W$23)) | X34: =IF($A34="","",SUMPRODUCT($C34:$K34,$O$24:$W$24)) | Y34: =IF($A34="","",SUMPRODUCT($C34:$K34,$O$25:$W$25)) | Z34: =IF($A34="","",SUMPRODUCT($C34:$K34,$O$26:$W$26))
A35: =IF(ISBLANK(CT!A35),"",CT!A35) | L35: =SUM(C35:K35) -> 0 | N35: =IF($A35="","",SUMIF($C$6:$K$6,">0",$C35:$K35)) | O35: =IF($A35="","",SUMIF($C$7:$K$7,">0",$C35:$K35)) | P35: =IF($A35="","",SUMIF($C$8:$K$8,">0",$C35:$K35)) | Q35: =IF($A35="","",SUMIF($C$9:$K$9,">0",$C35:$K35)) | R35: =IF($A35="","",SUMIF($C$10:$K$10,">0",$C35:$K35)) | S35: =IF($A35="","",SUMIF($C$11:$K$11,">0",$C35:$K35)) | U35: =IF($A35="","",SUMPRODUCT($C35:$K35,$O$21:$W$21)) | V35: =IF($A35="","",SUMPRODUCT($C35:$K35,$O$22:$W$22)) | W35: =IF($A35="","",SUMPRODUCT($C35:$K35,$O$23:$W$23)) | X35: =IF($A35="","",SUMPRODUCT($C35:$K35,$O$24:$W$24)) | Y35: =IF($A35="","",SUMPRODUCT($C35:$K35,$O$25:$W$25)) | Z35: =IF($A35="","",SUMPRODUCT($C35:$K35,$O$26:$W$26))
A36: =IF(ISBLANK(CT!A36),"",CT!A36) | L36: =SUM(C36:K36) -> 0 | N36: =IF($A36="","",SUMIF($C$6:$K$6,">0",$C36:$K36)) | O36: =IF($A36="","",SUMIF($C$7:$K$7,">0",$C36:$K36)) | P36: =IF($A36="","",SUMIF($C$8:$K$8,">0",$C36:$K36)) | Q36: =IF($A36="","",SUMIF($C$9:$K$9,">0",$C36:$K36)) | R36: =IF($A36="","",SUMIF($C$10:$K$10,">0",$C36:$K36)) | S36: =IF($A36="","",SUMIF($C$11:$K$11,">0",$C36:$K36)) | U36: =IF($A36="","",SUMPRODUCT($C36:$K36,$O$21:$W$21)) | V36: =IF($A36="","",SUMPRODUCT($C36:$K36,$O$22:$W$22)) | W36: =IF($A36="","",SUMPRODUCT($C36:$K36,$O$23:$W$23)) | X36: =IF($A36="","",SUMPRODUCT($C36:$K36,$O$24:$W$24)) | Y36: =IF($A36="","",SUMPRODUCT($C36:$K36,$O$25:$W$25)) | Z36: =IF($A36="","",SUMPRODUCT($C36:$K36,$O$26:$W$26))
A37: =IF(ISBLANK(CT!A37),"",CT!A37) | L37: =SUM(C37:K37) -> 0 | N37: =IF($A37="","",SUMIF($C$6:$K$6,">0",$C37:$K37)) | O37: =IF($A37="","",SUMIF($C$7:$K$7,">0",$C37:$K37)) | P37: =IF($A37="","",SUMIF($C$8:$K$8,">0",$C37:$K37)) | Q37: =IF($A37="","",SUMIF($C$9:$K$9,">0",$C37:$K37)) | R37: =IF($A37="","",SUMIF($C$10:$K$10,">0",$C37:$K37)) | S37: =IF($A37="","",SUMIF($C$11:$K$11,">0",$C37:$K37)) | U37: =IF($A37="","",SUMPRODUCT($C37:$K37,$O$21:$W$21)) | V37: =IF($A37="","",SUMPRODUCT($C37:$K37,$O$22:$W$22)) | W37: =IF($A37="","",SUMPRODUCT($C37:$K37,$O$23:$W$23)) | X37: =IF($A37="","",SUMPRODUCT($C37:$K37,$O$24:$W$24)) | Y37: =IF($A37="","",SUMPRODUCT($C37:$K37,$O$25:$W$25)) | Z37: =IF($A37="","",SUMPRODUCT($C37:$K37,$O$26:$W$26))
A38: =IF(ISBLANK(CT!A38),"",CT!A38) | L38: =SUM(C38:K38) -> 0 | N38: =IF($A38="","",SUMIF($C$6:$K$6,">0",$C38:$K38)) | O38: =IF($A38="","",SUMIF($C$7:$K$7,">0",$C38:$K38)) | P38: =IF($A38="","",SUMIF($C$8:$K$8,">0",$C38:$K38)) | Q38: =IF($A38="","",SUMIF($C$9:$K$9,">0",$C38:$K38)) | R38: =IF($A38="","",SUMIF($C$10:$K$10,">0",$C38:$K38)) | S38: =IF($A38="","",SUMIF($C$11:$K$11,">0",$C38:$K38)) | U38: =IF($A38="","",SUMPRODUCT($C38:$K38,$O$21:$W$21)) | V38: =IF($A38="","",SUMPRODUCT($C38:$K38,$O$22:$W$22)) | W38: =IF($A38="","",SUMPRODUCT($C38:$K38,$O$23:$W$23)) | X38: =IF($A38="","",SUMPRODUCT($C38:$K38,$O$24:$W$24)) | Y38: =IF($A38="","",SUMPRODUCT($C38:$K38,$O$25:$W$25)) | Z38: =IF($A38="","",SUMPRODUCT($C38:$K38,$O$26:$W$26))
A39: =IF(ISBLANK(CT!A39),"",CT!A39) | L39: =SUM(C39:K39) -> 0 | N39: =IF($A39="","",SUMIF($C$6:$K$6,">0",$C39:$K39)) | O39: =IF($A39="","",SUMIF($C$7:$K$7,">0",$C39:$K39)) | P39: =IF($A39="","",SUMIF($C$8:$K$8,">0",$C39:$K39)) | Q39: =IF($A39="","",SUMIF($C$9:$K$9,">0",$C39:$K39)) | R39: =IF($A39="","",SUMIF($C$10:$K$10,">0",$C39:$K39)) | S39: =IF($A39="","",SUMIF($C$11:$K$11,">0",$C39:$K39)) | U39: =IF($A39="","",SUMPRODUCT($C39:$K39,$O$21:$W$21)) | V39: =IF($A39="","",SUMPRODUCT($C39:$K39,$O$22:$W$22)) | W39: =IF($A39="","",SUMPRODUCT($C39:$K39,$O$23:$W$23)) | X39: =IF($A39="","",SUMPRODUCT($C39:$K39,$O$24:$W$24)) | Y39: =IF($A39="","",SUMPRODUCT($C39:$K39,$O$25:$W$25)) | Z39: =IF($A39="","",SUMPRODUCT($C39:$K39,$O$26:$W$26))
A40: =IF(ISBLANK(CT!A40),"",CT!A40) | L40: =SUM(C40:K40) -> 0 | N40: =IF($A40="","",SUMIF($C$6:$K$6,">0",$C40:$K40)) | O40: =IF($A40="","",SUMIF($C$7:$K$7,">0",$C40:$K40)) | P40: =IF($A40="","",SUMIF($C$8:$K$8,">0",$C40:$K40)) | Q40: =IF($A40="","",SUMIF($C$9:$K$9,">0",$C40:$K40)) | R40: =IF($A40="","",SUMIF($C$10:$K$10,">0",$C40:$K40)) | S40: =IF($A40="","",SUMIF($C$11:$K$11,">0",$C40:$K40)) | U40: =IF($A40="","",SUMPRODUCT($C40:$K40,$O$21:$W$21)) | V40: =IF($A40="","",SUMPRODUCT($C40:$K40,$O$22:$W$22)) | W40: =IF($A40="","",SUMPRODUCT($C40:$K40,$O$23:$W$23)) | X40: =IF($A40="","",SUMPRODUCT($C40:$K40,$O$24:$W$24)) | Y40: =IF($A40="","",SUMPRODUCT($C40:$K40,$O$25:$W$25)) | Z40: =IF($A40="","",SUMPRODUCT($C40:$K40,$O$26:$W$26))
A41: =IF(ISBLANK(CT!A41),"",CT!A41) | L41: =SUM(C41:K41) -> 0 | N41: =IF($A41="","",SUMIF($C$6:$K$6,">0",$C41:$K41)) | O41: =IF($A41="","",SUMIF($C$7:$K$7,">0",$C41:$K41)) | P41: =IF($A41="","",SUMIF($C$8:$K$8,">0",$C41:$K41)) | Q41: =IF($A41="","",SUMIF($C$9:$K$9,">0",$C41:$K41)) | R41: =IF($A41="","",SUMIF($C$10:$K$10,">0",$C41:$K41)) | S41: =IF($A41="","",SUMIF($C$11:$K$11,">0",$C41:$K41)) | U41: =IF($A41="","",SUMPRODUCT($C41:$K41,$O$21:$W$21)) | V41: =IF($A41="","",SUMPRODUCT($C41:$K41,$O$22:$W$22)) | W41: =IF($A41="","",SUMPRODUCT($C41:$K41,$O$23:$W$23)) | X41: =IF($A41="","",SUMPRODUCT($C41:$K41,$O$24:$W$24)) | Y41: =IF($A41="","",SUMPRODUCT($C41:$K41,$O$25:$W$25)) | Z41: =IF($A41="","",SUMPRODUCT($C41:$K41,$O$26:$W$26))
...

Sheet SectionA
A1: =CT!A1 -> CSE 2203+CSE 2204: Microprocessor and Microcontroller | BD1: 3 combinations | BF1: Stdev | BG1: =_xlfn.STDEV.P(AD4:AD9) -> 0 | BH1: =_xlfn.STDEV.P(AE4:AE9) -> 0 | BI1: =_xlfn.STDEV.P(AF4:AF9) -> 0 | BJ1: =_xlfn.STDEV.P(AG4:AG9) -> 0 | BK1: =MIN(BG1:BJ1) -> 0
A2: Allocated marks for Section-A in final question | AD2: 1 | AE2: 2 | AF2: 3 | AG2: 4 | AT2: =SUM(E11,J11) -> 0 | AU2: =SUM(E11,O11) -> 0 | AV2: =SUM(E11,T11) -> 0 | AW2: =SUM(J11,O11) -> 0 | AX2: =SUM(J11,T11) -> 0 | AY2: =SUM(T11,O11) -> 0 | AZ2: =E11 -> 0 | BA2: =J11 -> 0 | BB2: =O11 -> 0 | BC2: =T11 -> 0 | BF2: dist | BG2: =SQRT(SUMXMY2($BF$4:$BF$9,BG4:BG9)) -> #DIV/0! | BH2: =SQRT(SUMXMY2($BF$4:$BF$9,BH4:BH9)) -> #DIV/0! | BI2: =SQRT(SUMXMY2($BF$4:$BF$9,BI4:BI9)) -> #DIV/0! | BJ2: =SQRT(SUMXMY2($BF$4:$BF$9,BJ4:BJ9)) -> #DIV/0! | BK2: =MIN(BG2:BJ2) -> #DIV/0! | BL2: =MATCH(BK2,BG2:BJ2,0) -> #DIV/0! | BM2: {=INDEX(BG3:BJ3,1,BL2)} -> #DIV/0!
A3: CO No. | B3: 1(a) | C3: 1(b) | D3: 1(c) | E3: 1(d) | G3: 2(a) | H3: 2(b) | I3: 2(c) | J3: 2(d) | L3: 3(a) | M3: 3(b) | N3: 3(c) | O3: 3(d) | Q3: 4(a) | R3: 4(b) | S3: 4(c) | T3: 4(d) | AC3: Possible AnsComb | AD3: =AE2&","&AF2&","&AG2 -> 2,3,4 | AE3: =AD2&","&AF2&","&AG2 -> 1,3,4 | AF3: =AD2&","&AE2&","&AG2 -> 1,2,4 | AG3: =AD2&","&AE2&","&AF2 -> 1,2,3 | AH3: =AD2&","&AE2 -> 1,2 | AI3: =AD2&","&AF2 -> 1,3 | AJ3: =AD2&","&AG2 -> 1,4 | AK3: =AE2&","&AF2 -> 2,3 | AL3: =AE2&","&AG2 -> 2,4 | AM3: =AF2&","&AG2 -> 3,4 | AN3: =AD2&"" -> 1 | AO3: =AE2&"" -> 2 | AP3: =AF2&"" -> 3 | AQ3: =AG2&"" -> 4 | AR3: None | AT3: =AH3 -> 1,2 | AU3: =AI3 -> 1,3 | AV3: =AJ3 -> 1,4 | AW3: =AK3 -> 2,3 | AX3: =AL3 -> 2,4 | AY3: =AM3 -> 3,4 | AZ3: =VALUE(AN3) -> 1 | BA3: =AO3 -> 2 | BB3: =AP3 -> 3 | BC3: =AQ3 -> 4 | BD3: =AR3 -> None | BE3: CO msrd | BF3: unit v | BG3: =AD3 -> 2,3,4 | BH3: =AE3 -> 1,3,4 | BI3: =AF3 -> 1,2,4 | BJ3: =AG3 -> 1,2,3
A4: CO1 | V4: Don’t edit green/Blue/Yellow highlighted area | AC4: CO1 | AD4: =SUM(G4:T4) -> 0 | AE4: =SUM(B4,C4,D4,E4,L4,M4,N4,O4,Q4,R4,S4,T4) -> 0 | AF4: =SUM(B4:J4,Q4,R4,S4,T4) -> 0 | AG4: =SUM(B4:O4) -> 0 | AH4: =AT4+LOOKUP(AT$10,$AT$3:$BC$3,$AT4:$BC4) -> #DIV/0! | AI4: =AU4+LOOKUP(AU$10,$AT$3:$BC$3,$AT4:$BC4) -> #DIV/0! | AJ4: =AV4+LOOKUP(AV$10,$AT$3:$BC$3,$AT4:$BC4) -> #DIV/0! | AK4: =AW4+LOOKUP(AW$10,$AT$3:$BC$3,$AT4:$BC4) -> #DIV/0! | AL4: =AX4+LOOKUP(AX$10,$AT$3:$BC$3,$AT4:$BC4) -> #DIV/0! | AM4: =AY4+LOOKUP(AY$10,$AT$3:$BC$3,$AT4:$BC4) -> #DIV/0! | AN4: =AZ4+LOOKUP(AZ$10,$AT$3:$BC$3,$AT4:$BC4) -> #DIV/0! | AO4: =BA4+LOOKUP(BA$10,$AT$3:$BC$3,$AT4:$BC4) -> #DIV/0! | ... AQ4: =BC4+LOOKUP(BC$10,$AT$3:$BC$3,$AT4:$BC4) -> #DIV/0! | AR4: =INDEX(AD4:AG4,1,$AR$11) -> #DIV/0! | AT4: =SUM(B4:J4) -> 0 | AU4: =SUM(B4:E4,L4:O4) -> 0 | AV4: =SUM(B4:E4,Q4:T4) -> 0 | AW4: =SUM(G4:O4) -> 0 | AX4: =SUM(G4:J4,Q4:T4) -> 0 | AY4: =SUM(L4:O4,Q4:T4) -> 0 | AZ4: =SUM(B4:E4) -> 0 | BA4: =SUM(G4:J4) -> 0 | BB4: =SUM(L4:O4) -> 0 | BC4: =SUM(Q4:T4) -> 0 | BE4: =IF(SUM(AD4:AG4),1,0) -> 0 | BF4: =BE4/$BE$10 -> #DIV/0! | BG4: =AD4/SUM(AD$4:AD$9) -> #DIV/0! | BH4: =AE4/SUM(AE$4:AE$9) -> #DIV/0! | BI4: =AF4/SUM(AF$4:AF$9) -> #DIV/0! | BJ4: =AG4/SUM(AG$4:AG$9) -> #DIV/0!
A5: CO2 | AC5: CO2 | AD5: =SUM(G5:T5) -> 0 | AE5: =SUM(B5,C5,D5,E5,L5,M5,N5,O5,Q5,R5,S5,T5) -> 0 | AF5: =SUM(B5:J5,Q5,R5,S5,T5) -> 0 | AG5: =SUM(B5:O5) -> 0 | AH5: =AT5+LOOKUP(AT$10,$AT$3:$BC$3,$AT5:$BC5) -> #DIV/0! | AI5: =AU5+LOOKUP(AU$10,$AT$3:$BC$3,$AT5:$BC5) -> #DIV/0! | AJ5: =AV5+LOOKUP(AV$10,$AT$3:$BC$3,$AT5:$BC5) -> #DIV/0! | AK5: =AW5+LOOKUP(AW$10,$AT$3:$BC$3,$AT5:$BC5) -> #DIV/0! | AL5: =AX5+LOOKUP(AX$10,$AT$3:$BC$3,$AT5:$BC5) -> #DIV/0! | AM5: =AY5+LOOKUP(AY$10,$AT$3:$BC$3,$AT5:$BC5) -> #DIV/0! | AN5: =AZ5+LOOKUP(AZ$10,$AT$3:$BC$3,$AT5:$BC5) -> #DIV/0! | AO5: =BA5+LOOKUP(BA$10,$AT$3:$BC$3,$AT5:$BC5) -> #DIV/0! | ... AQ5: =BC5+LOOKUP(BC$10,$AT$3:$BC$3,$AT5:$BC5) -> #DIV/0! | AR5: =INDEX(AD5:AG5,1,$AR$11) -> #DIV/0! | AT5: =SUM(B5:J5) -> 0 | AU5: =SUM(B5:E5,L5:O5) -> 0 | AV5: =SUM(B5:E5,Q5:T5) -> 0 | AW5: =SUM(G5:O5) -> 0 | AX5: =SUM(G5:J5,Q5:T5) -> 0 | AY5: =SUM(L5:O5,Q5:T5) -> 0 | AZ5: =SUM(B5:E5) -> 0 | BA5: =SUM(G5:J5) -> 0 | BB5: =SUM(L5:O5) -> 0 | BC5: =SUM(Q5:T5) -> 0 | BE5: =IF(SUM(AD5:AG5),1,0) -> 0 | BF5: =BE5/$BE$10 -> #DIV/0! | BG5: =AD5/SUM(AD$4:AD$9) -> #DIV/0! | BH5: =AE5/SUM(AE$4:AE$9) -> #DIV/0! | BI5: =AF5/SUM(AF$4:AF$9) -> #DIV/0! | BJ5: =AG5/SUM(AG$4:AG$9) -> #DIV/0!
A6: CO3 | AC6: CO3 | AD6: =SUM(G6:T6) -> 0 | AE6: =SUM(B6,C6,D6,E6,L6,M6,N6,O6,Q6,R6,S6,T6) -> 0 | AF6: =SUM(B6:J6,Q6,R6,S6,T6) -> 0 | AG6: =SUM(B6:O6) -> 0 | AH6: =AT6+LOOKUP(AT$10,$AT$3:$BC$3,$AT6:$BC6) -> #DIV/0! | AI6: =AU6+LOOKUP(AU$10,$AT$3:$BC$3,$AT6:$BC6) -> #DIV/0! | AJ6: =AV6+LOOKUP(AV$10,$AT$3:$BC$3,$AT6:$BC6) -> #DIV/0! | AK6: =AW6+LOOKUP(AW$10,$AT$3:$BC$3,$AT6:$BC6) -> #DIV/0! | AL6: =AX6+LOOKUP(AX$10,$AT$3:$BC$3,$AT6:$BC6) -> #DIV/0! | AM6: =AY6+LOOKUP(AY$10,$AT$3:$BC$3,$AT6:$BC6) -> #DIV/0! | AN6: =AZ6+LOOKUP(AZ$10,$AT$3:$BC$3,$AT6:$BC6) -> #DIV/0! | AO6: =BA6+LOOKUP(BA$10,$AT$3:$BC$3,$AT6:$BC6) -> #DIV/0! | ... AQ6: =BC6+LOOKUP(BC$10,$AT$3:$BC$3,$AT6:$BC6) -> #DIV/0! | AR6: =INDEX(AD6:AG6,1,$AR$11) -> #DIV/0! | AT6: =SUM(B6:J6) -> 0 | AU6: =SUM(B6:E6,L6:O6) -> 0 | AV6: =SUM(B6:E6,Q6:T6) -> 0 | AW6: =SUM(G6:O6) -> 0 | AX6: =SUM(G6:J6,Q6:T6) -> 0 | AY6: =SUM(L6:O6,Q6:T6) -> 0 | AZ6: =SUM(B6:E6) -> 0 | BA6: =SUM(G6:J6) -> 0 | BB6: =SUM(L6:O6) -> 0 | BC6: =SUM(Q6:T6) -> 0 | BE6: =IF(SUM(AD6:AG6),1,0) -> 0 | BF6: =BE6/$BE$10 -> #DIV/0! | BG6: =AD6/SUM(AD$4:AD$9) -> #DIV/0! | BH6: =AE6/SUM(AE$4:AE$9) -> #DIV/0! | BI6: =AF6/SUM(AF$4:AF$9) -> #DIV/0! | BJ6: =AG6/SUM(AG$4:AG$9) -> #DIV/0!
A7: CO4 | AC7: CO4 | AD7: =SUM(G7:T7) -> 0 | AE7: =SUM(B7,C7,D7,E7,L7,M7,N7,O7,Q7,R7,S7,T7) -> 0 | AF7: =SUM(B7:J7,Q7,R7,S7,T7) -> 0 | AG7: =SUM(B7:O7) -> 0 | AH7: =AT7+LOOKUP(AT$10,$AT$3:$BC$3,$AT7:$BC7) -> #DIV/0! | AI7: =AU7+LOOKUP(AU$10,$AT$3:$BC$3,$AT7:$BC7) -> #DIV/0! | AJ7: =AV7+LOOKUP(AV$10,$AT$3:$BC$3,$AT7:$BC7) -> #DIV/0! | AK7: =AW7+LOOKUP(AW$10,$AT$3:$BC$3,$AT7:$BC7) -> #DIV/0! | AL7: =AX7+LOOKUP(AX$10,$AT$3:$BC$3,$AT7:$BC7) -> #DIV/0! | AM7: =AY7+LOOKUP(AY$10,$AT$3:$BC$3,$AT7:$BC7) -> #DIV/0! | AN7: =AZ7+LOOKUP(AZ$10,$AT$3:$BC$3,$AT7:$BC7) -> #DIV/0! | AO7: =BA7+LOOKUP(BA$10,$AT$3:$BC$3,$AT7:$BC7) -> #DIV/0! | ... AQ7: =BC7+LOOKUP(BC$10,$AT$3:$BC$3,$AT7:$BC7) -> #DIV/0! | AR7: =INDEX(AD7:AG7,1,$AR$11) -> #DIV/0! | AT7: =SUM(B7:J7) -> 0 | AU7: =SUM(B7:E7,L7:O7) -> 0 | AV7: =SUM(B7:E7,Q7:T7) -> 0 | AW7: =SUM(G7:O7) -> 0 | AX7: =SUM(G7:J7,Q7:T7) -> 0 | AY7: =SUM(L7:O7,Q7:T7) -> 0 | AZ7: =SUM(B7:E7) -> 0 | BA7: =SUM(G7:J7) -> 0 | BB7: =SUM(L7:O7) -> 0 | BC7: =SUM(Q7:T7) -> 0 | BE7: =IF(SUM(AD7:AG7),1,0) -> 0 | BF7: =BE7/$BE$10 -> #DIV/0! | BG7: =AD7/SUM(AD$4:AD$9) -> #DIV/0! | BH7: =AE7/SUM(AE$4:AE$9) -> #DIV/0! | BI7: =AF7/SUM(AF$4:AF$9) -> #DIV/0! | BJ7: =AG7/SUM(AG$4:AG$9) -> #DIV/0!
A8: CO5 | AC8: CO5 | AD8: =SUM(G8:T8) -> 0 | AE8: =SUM(B8,C8,D8,E8,L8,M8,N8,O8,Q8,R8,S8,T8) -> 0 | AF8: =SUM(B8:J8,Q8,R8,S8,T8) -> 0 | AG8: =SUM(B8:O8) -> 0 | AH8: =AT8+LOOKUP(AT$10,$AT$3:$BC$3,$AT8:$BC8) -> #DIV/0! | AI8: =AU8+LOOKUP(AU$10,$AT$3:$BC$3,$AT8:$BC8) -> #DIV/0! | AJ8: =AV8+LOOKUP(AV$10,$AT$3:$BC$3,$AT8:$BC8) -> #DIV/0! | AK8: =AW8+LOOKUP(AW$10,$AT$3:$BC$3,$AT8:$BC8) -> #DIV/0! | AL8: =AX8+LOOKUP(AX$10,$AT$3:$BC$3,$AT8:$BC8) -> #DIV/0! | AM8: =AY8+LOOKUP(AY$10,$AT$3:$BC$3,$AT8:$BC8) -> #DIV/0! | AN8: =AZ8+LOOKUP(AZ$10,$AT$3:$BC$3,$AT8:$BC8) -> #DIV/0! | AO8: =BA8+LOOKUP(BA$10,$AT$3:$BC$3,$AT8:$BC8) -> #DIV/0! | ... AQ8: =BC8+LOOKUP(BC$10,$AT$3:$BC$3,$AT8:$BC8) -> #DIV/0! | AR8: =INDEX(AD8:AG8,1,$AR$11) -> #DIV/0! | AT8: =SUM(B8:J8) -> 0 | AU8: =SUM(B8:E8,L8:O8) -> 0 | AV8: =SUM(B8:E8,Q8:T8) -> 0 | AW8: =SUM(G8:O8) -> 0 | AX8: =SUM(G8:J8,Q8:T8) -> 0 | AY8: =SUM(L8:O8,Q8:T8) -> 0 | AZ8: =SUM(B8:E8) -> 0 | BA8: =SUM(G8:J8) -> 0 | BB8: =SUM(L8:O8) -> 0 | BC8: =SUM(Q8:T8) -> 0 | BD8: =MIN(AP8:AS8) -> #DIV/0! | BE8: =IF(SUM(AD8:AG8),1,0) -> 0 | BF8: =BE8/$BE$10 -> #DIV/0! | BG8: =AD8/SUM(AD$4:AD$9) -> #DIV/0! | BH8: =AE8/SUM(AE$4:AE$9) -> #DIV/0! | BI8: =AF8/SUM(AF$4:AF$9) -> #DIV/0! | BJ8: =AG8/SUM(AG$4:AG$9) -> #DIV/0!
A9: CO6 | AC9: CO6 | AD9: =SUM(G9:T9) -> 0 | AE9: =SUM(B9,C9,D9,E9,L9,M9,N9,O9,Q9,R9,S9,T9) -> 0 | AF9: =SUM(B9:J9,Q9,R9,S9,T9) -> 0 | AG9: =SUM(B9:O9) -> 0 | AH9: =AT9+LOOKUP(AT$10,$AT$3:$BC$3,$AT9:$BC9) -> #DIV/0! | AI9: =AU9+LOOKUP(AU$10,$AT$3:$BC$3,$AT9:$BC9) -> #DIV/0! | AJ9: =AV9+LOOKUP(AV$10,$AT$3:$BC$3,$AT9:$BC9) -> #DIV/0! | AK9: =AW9+LOOKUP(AW$10,$AT$3:$BC$3,$AT9:$BC9) -> #DIV/0! | AL9: =AX9+LOOKUP(AX$10,$AT$3:$BC$3,$AT9:$BC9) -> #DIV/0! | AM9: =AY9+LOOKUP(AY$10,$AT$3:$BC$3,$AT9:$BC9) -> #DIV/0! | AN9: =AZ9+LOOKUP(AZ$10,$AT$3:$BC$3,$AT9:$BC9) -> #DIV/0! | AO9: =BA9+LOOKUP(BA$10,$AT$3:$BC$3,$AT9:$BC9) -> #DIV/0! | ... AQ9: =BC9+LOOKUP(BC$10,$AT$3:$BC$3,$AT9:$BC9) -> #DIV/0! | AR9: =INDEX(AD9:AG9,1,$AR$11) -> #DIV/0! | AT9: =SUM(B9:J9) -> 0 | AU9: =SUM(B9:E9,L9:O9) -> 0 | AV9: =SUM(B9:E9,Q9:T9) -> 0 | AW9: =SUM(G9:O9) -> 0 | AX9: =SUM(G9:J9,Q9:T9) -> 0 | AY9: =SUM(L9:O9,Q9:T9) -> 0 | AZ9: =SUM(B9:E9) -> 0 | BA9: =SUM(G9:J9) -> 0 | BB9: =SUM(L9:O9) -> 0 | BC9: =SUM(Q9:T9) -> 0 | BD9: =MIN(AP9:AS9) -> #DIV/0! | BE9: =IF(SUM(AD9:AG9),1,0) -> 0 | BF9: =BE9/$BE$10 -> #DIV/0! | BG9: =AD9/SUM(AD$4:AD$9) -> #DIV/0! | BH9: =AE9/SUM(AE$4:AE$9) -> #DIV/0! | BI9: =AF9/SUM(AF$4:AF$9) -> #DIV/0! | BJ9: =AG9/SUM(AG$4:AG$9) -> #DIV/0!
B10: =SUM(B4:B8) -> 0 | C10: =SUM(C4:C8) -> 0 | D10: =SUM(D4:D8) -> 0 | E10: =SUM(E4:E8) -> 0 | G10: =SUM(G4:G8) -> 0 | H10: =SUM(H4:H8) -> 0 | I10: =SUM(I4:I8) -> 0 | J10: =SUM(J4:J8) -> 0 | L10: =SUM(L4:L8) -> 0 | M10: =SUM(M4:M8) -> 0 | N10: =SUM(N4:N8) -> 0 | O10: =SUM(O4:O8) -> 0 | Q10: =SUM(Q4:Q8) -> 0 | R10: =SUM(R4:R8) -> 0 | S10: =SUM(S4:S8) -> 0 | T10: =SUM(T4:T8) -> 0 | AR10: =BM2 -> #DIV/0! | AT10: =BG92 -> #DIV/0! | AU10: =BG93 -> #DIV/0! | AV10: =BG94 -> #DIV/0! | AW10: =BG95 -> #DIV/0! | AX10: =BG96 -> #DIV/0! | AY10: =BG97 -> #DIV/0! | AZ10: =BG98 -> #DIV/0! | BA10: =BG99 -> #DIV/0! | BB10: =BG100 -> #DIV/0! | BC10: =BG101 -> #DIV/0! | BE10: =SUM(BE4:BE9) -> 0 | BF10: =SUM(BF4:BF9) -> #DIV/0! | BG10: =SUM(BG4:BG9) -> #DIV/0! | BH10: =SUM(BH4:BH9) -> #DIV/0! | BI10: =SUM(BI4:BI9) -> #DIV/0! | BJ10: =SUM(BJ4:BJ9) -> #DIV/0!
E11: =SUM(B10:E10) -> 0 | J11: =SUM(G10:J10) -> 0 | O11: =SUM(L10:O10) -> 0 | T11: =SUM(Q10:T10) -> 0 | AC11: Ret Indx | AD11: 2 | AE11: 3 | AF11: 4 | AG11: 5 | AH11: 6 | AI11: 7 | AR11: =BL2 -> #DIV/0!
B12: =IF(E11,IF(E11<>35,"Total marks mismatch", ""),"") | G12: =IF(J11,IF(J11<>35,"Total marks mismatch", ""),"") | L12: =IF(O11,IF(O11<>35,"Total marks mismatch", ""),"") | Q12: =IF(T11,IF(T11<>35,"Total marks mismatch", ""),"")
AJ14: =IF(SUM(AJ17:AJ141),1,0) -> 0 | AK14: =IF(SUM(AK17:AK141),1,0) -> 0 | AL14: =IF(SUM(AL17:AL141),1,0) -> 0 | AM14: =IF(SUM(AM17:AM141),1,0) -> 0 | AN14: =IF(SUM(AN17:AN141),1,0) -> 0 | AO14: =IF(SUM(AO17:AO141),1,0) -> 0
A15: Obtained marks for Section-A | V15: Total Marks obtained Per CO | AC15: Q.No | AJ15: CO marks distribution per student | AR15: Possible AnsComb | AT15: =AT3 -> 1,2 | AU15: =AU3 -> 1,3 | AV15: =AV3 -> 1,4 | AW15: =AW3 -> 2,3 | AX15: =AX3 -> 2,4 | AY15: =AY3 -> 3,4 | AZ15: =AZ3 -> 1 | BA15: =BA3 -> 2 | ... BD15: =BD3 -> None
A16: Roll | B16: 1(a) | C16: 1(b) | D16: 1(c) | E16: 1(d) | G16: 2(a) | H16: 2(b) | I16: 2(c) | J16: 2(d) | L16: 3(a) | M16: 3(b) | N16: 3(c) | O16: 3(d) | Q16: 4(a) | R16: 4(b) | S16: 4(c) | T16: 4(d) | U16: Total | V16: CO1 | W16: CO2 | X16: CO3 | Y16: CO4 | Z16: CO5 | AA16: CO6 | AC16: =AD2 -> 1 | AD16: =AE2 -> 2 | AE16: =AF2 -> 3 | AF16: =AG2 -> 4 | AG16: ZeroCount | AH16: AnsComb | AJ16: CO1 | AK16: CO2 | AL16: CO3 | AM16: CO4 | AN16: CO5 | AO16: CO6 | AR16: CO1 | AT16: =AT4/AT$2 -> #DIV/0! | AU16: =AU4/AU$2 -> #DIV/0! | AV16: =AV4/AV$2 -> #DIV/0! | AW16: =AW4/AW$2 -> #DIV/0! | AX16: =AX4/AX$2 -> #DIV/0! | AY16: =AY4/AY$2 -> #DIV/0! | AZ16: =AZ4/AZ$2 -> #DIV/0! | BA16: =BA4/BA$2 -> #DIV/0! | ... BC16: =BC4/BC$2 -> #DIV/0! | BD16: =MIN(AO16:AS16) -> 0
A17: =IF(ISBLANK(CT!A32),"",CT!A32) | U17: =IF($A17="","",SUM(B17:T17)) | V17: =IF($A17="","",SUMIF($B$4:$T$4,">0",$B17:$T17)) | W17: =IF($A17="","",SUMIF($B$5:$T$5,">0",$B17:$T17)) | X17: =IF($A17="","",SUMIF($B$6:$T$6,">0",$B17:$T17)) | Y17: =IF($A17="","",SUMIF($B$7:$T$7,">0",$B17:$T17)) | Z17: =IF($A17="","",SUMIF($B$8:$T$8,">0",$B17:$T17)) | AA17: =IF($A17="","",SUMIF($B$9:$T$9,">0",$B17:$T17)) | AC17: =IF($A17="","",SUM(B17:E17)) | AD17: =IF($A17="","",SUM(G17:J17)) | AE17: =IF($A17="","",SUM(L17:O17)) | AF17: =IF($A17="","",SUM(Q17:T17)) | AG17: =COUNTIF(AC17:AF17,0) -> 0 | AH17: =IF(SUM(AC17:AF17)=0,"None",CONCATENATE(IF(AC17>0,AC$16&",",""),IF(AD17>0,AD$16&",",""),IF(AE17>0,AE$16&",",""),IF(AF17>0,AF$16,""))) -> None | AI17: =IF(AH17<>"",IF(RIGHT(AH17,1)=",",LEFT(AH17,LEN(AH17)-1),AH17),"None") -> None | AJ17: =IF($A17="","",HLOOKUP($AI17,$AD$3:$AR$9,AD$11,FALSE)) | AK17: =IF($A17="","",HLOOKUP($AI17,$AD$3:$AR$9,AE$11,FALSE)) | AL17: =IF($A17="","",HLOOKUP($AI17,$AD$3:$AR$9,AF$11,FALSE)) | AM17: =IF($A17="","",HLOOKUP($AI17,$AD$3:$AR$9,AG$11,FALSE)) | AN17: =IF($A17="","",HLOOKUP($AI17,$AD$3:$AR$9,AH$11,FALSE)) | AO17: =IF($A17="","",HLOOKUP($AI17,$AD$3:$AR$9,AI$11,FALSE)) | AP17: =SUM(AJ17:AO17) -> 0 | AR17: CO2 | AT17: =AT5/AT$2 -> #DIV/0! | AU17: =AU5/AU$2 -> #DIV/0! | AV17: =AV5/AV$2 -> #DIV/0! | AW17: =AW5/AW$2 -> #DIV/0! | AX17: =AX5/AX$2 -> #DIV/0! | AY17: =AY5/AY$2 -> #DIV/0! | AZ17: =AZ5/AZ$2 -> #DIV/0! | BA17: =BA5/BA$2 -> #DIV/0! | ... BC17: =BC5/BC$2 -> #DIV/0! | BD17: =MIN(AO17:AS17) -> 0
A18: =IF(ISBLANK(CT!A33),"",CT!A33) | U18: =IF($A18="","",SUM(B18:T18)) | V18: =IF($A18="","",SUMIF($B$4:$T$4,">0",$B18:$T18)) | W18: =IF($A18="","",SUMIF($B$5:$T$5,">0",$B18:$T18)) | X18: =IF($A18="","",SUMIF($B$6:$T$6,">0",$B18:$T18)) | Y18: =IF($A18="","",SUMIF($B$7:$T$7,">0",$B18:$T18)) | Z18: =IF($A18="","",SUMIF($B$8:$T$8,">0",$B18:$T18)) | AA18: =IF($A18="","",SUMIF($B$9:$T$9,">0",$B18:$T18)) | AC18: =IF($A18="","",SUM(B18:E18)) | AD18: =IF($A18="","",SUM(G18:J18)) | AE18: =IF($A18="","",SUM(L18:O18)) | AF18: =IF($A18="","",SUM(Q18:T18)) | AG18: =COUNTIF(AC18:AF18,0) -> 0 | AH18: =IF(SUM(AC18:AF18)=0,"None",CONCATENATE(IF(AC18>0,AC$16&",",""),IF(AD18>0,AD$16&",",""),IF(AE18>0,AE$16&",",""),IF(AF18>0,AF$16,""))) -> None | AI18: =IF(AH18<>"",IF(RIGHT(AH18,1)=",",LEFT(AH18,LEN(AH18)-1),AH18),"None") -> None | AJ18: =IF($A18="","",HLOOKUP($AI18,$AD$3:$AR$9,AD$11,FALSE)) | AK18: =IF($A18="","",HLOOKUP($AI18,$AD$3:$AR$9,AE$11,FALSE)) | AL18: =IF($A18="","",HLOOKUP($AI18,$AD$3:$AR$9,AF$11,FALSE)) | AM18: =IF($A18="","",HLOOKUP($AI18,$AD$3:$AR$9,AG$11,FALSE)) | AN18: =IF($A18="","",HLOOKUP($AI18,$AD$3:$AR$9,AH$11,FALSE)) | AO18: =IF($A18="","",HLOOKUP($AI18,$AD$3:$AR$9,AI$11,FALSE)) | AP18: =SUM(AJ18:AO18) -> 0 | AR18: CO3 | AT18: =AT6/AT$2 -> #DIV/0! | AU18: =AU6/AU$2 -> #DIV/0! | AV18: =AV6/AV$2 -> #DIV/0! | AW18: =AW6/AW$2 -> #DIV/0! | AX18: =AX6/AX$2 -> #DIV/0! | AY18: =AY6/AY$2 -> #DIV/0! | AZ18: =AZ6/AZ$2 -> #DIV/0! | BA18: =BA6/BA$2 -> #DIV/0! | ... BC18: =BC6/BC$2 -> #DIV/0! | BD18: =MIN(AO18:AS18) -> 0
A19: =IF(ISBLANK(CT!A34),"",CT!A34) | U19: =IF($A19="","",SUM(B19:T19)) | V19: =IF($A19="","",SUMIF($B$4:$T$4,">0",$B19:$T19)) | W19: =IF($A19="","",SUMIF($B$5:$T$5,">0",$B19:$T19)) | X19: =IF($A19="","",SUMIF($B$6:$T$6,">0",$B19:$T19)) | Y19: =IF($A19="","",SUMIF($B$7:$T$7,">0",$B19:$T19)) | Z19: =IF($A19="","",SUMIF($B$8:$T$8,">0",$B19:$T19)) | AA19: =IF($A19="","",SUMIF($B$9:$T$9,">0",$B19:$T19)) | AC19: =IF($A19="","",SUM(B19:E19)) | AD19: =IF($A19="","",SUM(G19:J19)) | AE19: =IF($A19="","",SUM(L19:O19)) | AF19: =IF($A19="","",SUM(Q19:T19)) | AG19: =COUNTIF(AC19:AF19,0) -> 0 | AH19: =IF(SUM(AC19:AF19)=0,"None",CONCATENATE(IF(AC19>0,AC$16&",",""),IF(AD19>0,AD$16&",",""),IF(AE19>0,AE$16&",",""),IF(AF19>0,AF$16,""))) -> None | AI19: =IF(AH19<>"",IF(RIGHT(AH19,1)=",",LEFT(AH19,LEN(AH19)-1),AH19),"None") -> None | AJ19: =IF($A19="","",HLOOKUP($AI19,$AD$3:$AR$9,AD$11,FALSE)) | AK19: =IF($A19="","",HLOOKUP($AI19,$AD$3:$AR$9,AE$11,FALSE)) | AL19: =IF($A19="","",HLOOKUP($AI19,$AD$3:$AR$9,AF$11,FALSE)) | AM19: =IF($A19="","",HLOOKUP($AI19,$AD$3:$AR$9,AG$11,FALSE)) | AN19: =IF($A19="","",HLOOKUP($AI19,$AD$3:$AR$9,AH$11,FALSE)) | AO19: =IF($A19="","",HLOOKUP($AI19,$AD$3:$AR$9,AI$11,FALSE)) | AP19: =SUM(AJ19:AO19) -> 0 | AR19: CO4 | AT19: =AT7/AT$2 -> #DIV/0! | AU19: =AU7/AU$2 -> #DIV/0! | AV19: =AV7/AV$2 -> #DIV/0! | AW19: =AW7/AW$2 -> #DIV/0! | AX19: =AX7/AX$2 -> #DIV/0! | AY19: =AY7/AY$2 -> #DIV/0! | AZ19: =AZ7/AZ$2 -> #DIV/0! | BA19: =BA7/BA$2 -> #DIV/0! | ... BC19: =BC7/BC$2 -> #DIV/0! | BD19: =MIN(AO19:AS19) -> 0
A20: =IF(ISBLANK(CT!A35),"",CT!A35) | U20: =IF($A20="","",SUM(B20:T20)) | V20: =IF($A20="","",SUMIF($B$4:$T$4,">0",$B20:$T20)) | W20: =IF($A20="","",SUMIF($B$5:$T$5,">0",$B20:$T20)) | X20: =IF($A20="","",SUMIF($B$6:$T$6,">0",$B20:$T20)) | Y20: =IF($A20="","",SUMIF($B$7:$T$7,">0",$B20:$T20)) | Z20: =IF($A20="","",SUMIF($B$8:$T$8,">0",$B20:$T20)) | AA20: =IF($A20="","",SUMIF($B$9:$T$9,">0",$B20:$T20)) | AC20: =IF($A20="","",SUM(B20:E20)) | AD20: =IF($A20="","",SUM(G20:J20)) | AE20: =IF($A20="","",SUM(L20:O20)) | AF20: =IF($A20="","",SUM(Q20:T20)) | AG20: =COUNTIF(AC20:AF20,0) -> 0 | AH20: =IF(SUM(AC20:AF20)=0,"None",CONCATENATE(IF(AC20>0,AC$16&",",""),IF(AD20>0,AD$16&",",""),IF(AE20>0,AE$16&",",""),IF(AF20>0,AF$16,""))) -> None | AI20: =IF(AH20<>"",IF(RIGHT(AH20,1)=",",LEFT(AH20,LEN(AH20)-1),AH20),"None") -> None | AJ20: =IF($A20="","",HLOOKUP($AI20,$AD$3:$AR$9,AD$11,FALSE)) | AK20: =IF($A20="","",HLOOKUP($AI20,$AD$3:$AR$9,AE$11,FALSE)) | AL20: =IF($A20="","",HLOOKUP($AI20,$AD$3:$AR$9,AF$11,FALSE)) | AM20: =IF($A20="","",HLOOKUP($AI20,$AD$3:$AR$9,AG$11,FALSE)) | AN20: =IF($A20="","",HLOOKUP($AI20,$AD$3:$AR$9,AH$11,FALSE)) | AO20: =IF($A20="","",HLOOKUP($AI20,$AD$3:$AR$9,AI$11,FALSE)) | AP20: =SUM(AJ20:AO20) -> 0 | AR20: CO5 | AT20: =AT8/AT$2 -> #DIV/0! | AU20: =AU8/AU$2 -> #DIV/0! | AV20: =AV8/AV$2 -> #DIV/0! | AW20: =AW8/AW$2 -> #DIV/0! | AX20: =AX8/AX$2 -> #DIV/0! | AY20: =AY8/AY$2 -> #DIV/0! | AZ20: =AZ8/AZ$2 -> #DIV/0! | BA20: =BA8/BA$2 -> #DIV/0! | ... BC20: =BC8/BC$2 -> #DIV/0! | BD20: =MIN(AO20:AS20) -> 0
A21: =IF(ISBLANK(CT!A36),"",CT!A36) | U21: =IF($A21="","",SUM(B21:T21)) | V21: =IF($A21="","",SUMIF($B$4:$T$4,">0",$B21:$T21)) | W21: =IF($A21="","",SUMIF($B$5:$T$5,">0",$B21:$T21)) | X21: =IF($A21="","",SUMIF($B$6:$T$6,">0",$B21:$T21)) | Y21: =IF($A21="","",SUMIF($B$7:$T$7,">0",$B21:$T21)) | Z21: =IF($A21="","",SUMIF($B$8:$T$8,">0",$B21:$T21)) | AA21: =IF($A21="","",SUMIF($B$9:$T$9,">0",$B21:$T21)) | AC21: =IF($A21="","",SUM(B21:E21)) | AD21: =IF($A21="","",SUM(G21:J21)) | AE21: =IF($A21="","",SUM(L21:O21)) | AF21: =IF($A21="","",SUM(Q21:T21)) | AG21: =COUNTIF(AC21:AF21,0) -> 0 | AH21: =IF(SUM(AC21:AF21)=0,"None",CONCATENATE(IF(AC21>0,AC$16&",",""),IF(AD21>0,AD$16&",",""),IF(AE21>0,AE$16&",",""),IF(AF21>0,AF$16,""))) -> None | AI21: =IF(AH21<>"",IF(RIGHT(AH21,1)=",",LEFT(AH21,LEN(AH21)-1),AH21),"None") -> None | AJ21: =IF($A21="","",HLOOKUP($AI21,$AD$3:$AR$9,AD$11,FALSE)) | AK21: =IF($A21="","",HLOOKUP($AI21,$AD$3:$AR$9,AE$11,FALSE)) | AL21: =IF($A21="","",HLOOKUP($AI21,$AD$3:$AR$9,AF$11,FALSE)) | AM21: =IF($A21="","",HLOOKUP($AI21,$AD$3:$AR$9,AG$11,FALSE)) | AN21: =IF($A21="","",HLOOKUP($AI21,$AD$3:$AR$9,AH$11,FALSE)) | AO21: =IF($A21="","",HLOOKUP($AI21,$AD$3:$AR$9,AI$11,FALSE)) | AP21: =SUM(AJ21:AO21) -> 0 | AR21: CO6 | AT21: =AT9/AT$2 -> #DIV/0! | AU21: =AU9/AU$2 -> #DIV/0! | AV21: =AV9/AV$2 -> #DIV/0! | AW21: =AW9/AW$2 -> #DIV/0! | AX21: =AX9/AX$2 -> #DIV/0! | AY21: =AY9/AY$2 -> #DIV/0! | AZ21: =AZ9/AZ$2 -> #DIV/0! | BA21: =BA9/BA$2 -> #DIV/0! | ... BC21: =BC9/BC$2 -> #DIV/0! | BD21: =MIN(AO21:AS21) -> 0
A22: =IF(ISBLANK(CT!A37),"",CT!A37) | U22: =IF($A22="","",SUM(B22:T22)) | V22: =IF($A22="","",SUMIF($B$4:$T$4,">0",$B22:$T22)) | W22: =IF($A22="","",SUMIF($B$5:$T$5,">0",$B22:$T22)) | X22: =IF($A22="","",SUMIF($B$6:$T$6,">0",$B22:$T22)) | Y22: =IF($A22="","",SUMIF($B$7:$T$7,">0",$B22:$T22)) | Z22: =IF($A22="","",SUMIF($B$8:$T$8,">0",$B22:$T22)) | AA22: =IF($A22="","",SUMIF($B$9:$T$9,">0",$B22:$T22)) | AC22: =IF($A22="","",SUM(B22:E22)) | AD22: =IF($A22="","",SUM(G22:J22)) | AE22: =IF($A22="","",SUM(L22:O22)) | AF22: =IF($A22="","",SUM(Q22:T22)) | AG22: =COUNTIF(AC22:AF22,0) -> 0 | AH22: =IF(SUM(AC22:AF22)=0,"None",CONCATENATE(IF(AC22>0,AC$16&",",""),IF(AD22>0,AD$16&",",""),IF(AE22>0,AE$16&",",""),IF(AF22>0,AF$16,""))) -> None | AI22: =IF(AH22<>"",IF(RIGHT(AH22,1)=",",LEFT(AH22,LEN(AH22)-1),AH22),"None") -> None | AJ22: =IF($A22="","",HLOOKUP($AI22,$AD$3:$AR$9,AD$11,FALSE)) | AK22: =IF($A22="","",HLOOKUP($AI22,$AD$3:$AR$9,AE$11,FALSE)) | AL22: =IF($A22="","",HLOOKUP($AI22,$AD$3:$AR$9,AF$11,FALSE)) | AM22: =IF($A22="","",HLOOKUP($AI22,$AD$3:$AR$9,AG$11,FALSE)) | AN22: =IF($A22="","",HLOOKUP($AI22,$AD$3:$AR$9,AH$11,FALSE)) | AO22: =IF($A22="","",HLOOKUP($AI22,$AD$3:$AR$9,AI$11,FALSE)) | AP22: =SUM(AJ22:AO22) -> 0
A23: =IF(ISBLANK(CT!A38),"",CT!A38) | U23: =IF($A23="","",SUM(B23:T23)) | V23: =IF($A23="","",SUMIF($B$4:$T$4,">0",$B23:$T23)) | W23: =IF($A23="","",SUMIF($B$5:$T$5,">0",$B23:$T23)) | X23: =IF($A23="","",SUMIF($B$6:$T$6,">0",$B23:$T23)) | Y23: =IF($A23="","",SUMIF($B$7:$T$7,">0",$B23:$T23)) | Z23: =IF($A23="","",SUMIF($B$8:$T$8,">0",$B23:$T23)) | AA23: =IF($A23="","",SUMIF($B$9:$T$9,">0",$B23:$T23)) | AC23: =IF($A23="","",SUM(B23:E23)) | AD23: =IF($A23="","",SUM(G23:J23)) | AE23: =IF($A23="","",SUM(L23:O23)) | AF23: =IF($A23="","",SUM(Q23:T23)) | AG23: =COUNTIF(AC23:AF23,0) -> 0 | AH23: =IF(SUM(AC23:AF23)=0,"None",CONCATENATE(IF(AC23>0,AC$16&",",""),IF(AD23>0,AD$16&",",""),IF(AE23>0,AE$16&",",""),IF(AF23>0,AF$16,""))) -> None | AI23: =IF(AH23<>"",IF(RIGHT(AH23,1)=",",LEFT(AH23,LEN(AH23)-1),AH23),"None") -> None | AJ23: =IF($A23="","",HLOOKUP($AI23,$AD$3:$AR$9,AD$11,FALSE)) | AK23: =IF($A23="","",HLOOKUP($AI23,$AD$3:$AR$9,AE$11,FALSE)) | AL23: =IF($A23="","",HLOOKUP($AI23,$AD$3:$AR$9,AF$11,FALSE)) | AM23: =IF($A23="","",HLOOKUP($AI23,$AD$3:$AR$9,AG$11,FALSE)) | AN23: =IF($A23="","",HLOOKUP($AI23,$AD$3:$AR$9,AH$11,FALSE)) | AO23: =IF($A23="","",HLOOKUP($AI23,$AD$3:$AR$9,AI$11,FALSE)) | AP23: =SUM(AJ23:AO23) -> 0
A24: =IF(ISBLANK(CT!A39),"",CT!A39) | U24: =IF($A24="","",SUM(B24:T24)) | V24: =IF($A24="","",SUMIF($B$4:$T$4,">0",$B24:$T24)) | W24: =IF($A24="","",SUMIF($B$5:$T$5,">0",$B24:$T24)) | X24: =IF($A24="","",SUMIF($B$6:$T$6,">0",$B24:$T24)) | Y24: =IF($A24="","",SUMIF($B$7:$T$7,">0",$B24:$T24)) | Z24: =IF($A24="","",SUMIF($B$8:$T$8,">0",$B24:$T24)) | AA24: =IF($A24="","",SUMIF($B$9:$T$9,">0",$B24:$T24)) | AC24: =IF($A24="","",SUM(B24:E24)) | AD24: =IF($A24="","",SUM(G24:J24)) | AE24: =IF($A24="","",SUM(L24:O24)) | AF24: =IF($A24="","",SUM(Q24:T24)) | AG24: =COUNTIF(AC24:AF24,0) -> 0 | AH24: =IF(SUM(AC24:AF24)=0,"None",CONCATENATE(IF(AC24>0,AC$16&",",""),IF(AD24>0,AD$16&",",""),IF(AE24>0,AE$16&",",""),IF(AF24>0,AF$16,""))) -> None | AI24: =IF(AH24<>"",IF(RIGHT(AH24,1)=",",LEFT(AH24,LEN(AH24)-1),AH24),"None") -> None | AJ24: =IF($A24="","",HLOOKUP($AI24,$AD$3:$AR$9,AD$11,FALSE)) | AK24: =IF($A24="","",HLOOKUP($AI24,$AD$3:$AR$9,AE$11,FALSE)) | AL24: =IF($A24="","",HLOOKUP($AI24,$AD$3:$AR$9,AF$11,FALSE)) | AM24: =IF($A24="","",HLOOKUP($AI24,$AD$3:$AR$9,AG$11,FALSE)) | AN24: =IF($A24="","",HLOOKUP($AI24,$AD$3:$AR$9,AH$11,FALSE)) | AO24: =IF($A24="","",HLOOKUP($AI24,$AD$3:$AR$9,AI$11,FALSE)) | AP24: =SUM(AJ24:AO24) -> 0 | AT24: Distane
A25: =IF(ISBLANK(CT!A40),"",CT!A40) | U25: =IF($A25="","",SUM(B25:T25)) | V25: =IF($A25="","",SUMIF($B$4:$T$4,">0",$B25:$T25)) | W25: =IF($A25="","",SUMIF($B$5:$T$5,">0",$B25:$T25)) | X25: =IF($A25="","",SUMIF($B$6:$T$6,">0",$B25:$T25)) | Y25: =IF($A25="","",SUMIF($B$7:$T$7,">0",$B25:$T25)) | Z25: =IF($A25="","",SUMIF($B$8:$T$8,">0",$B25:$T25)) | AA25: =IF($A25="","",SUMIF($B$9:$T$9,">0",$B25:$T25)) | AC25: =IF($A25="","",SUM(B25:E25)) | AD25: =IF($A25="","",SUM(G25:J25)) | AE25: =IF($A25="","",SUM(L25:O25)) | AF25: =IF($A25="","",SUM(Q25:T25)) | AG25: =COUNTIF(AC25:AF25,0) -> 0 | AH25: =IF(SUM(AC25:AF25)=0,"None",CONCATENATE(IF(AC25>0,AC$16&",",""),IF(AD25>0,AD$16&",",""),IF(AE25>0,AE$16&",",""),IF(AF25>0,AF$16,""))) -> None | AI25: =IF(AH25<>"",IF(RIGHT(AH25,1)=",",LEFT(AH25,LEN(AH25)-1),AH25),"None") -> None | AJ25: =IF($A25="","",HLOOKUP($AI25,$AD$3:$AR$9,AD$11,FALSE)) | AK25: =IF($A25="","",HLOOKUP($AI25,$AD$3:$AR$9,AE$11,FALSE)) | AL25: =IF($A25="","",HLOOKUP($AI25,$AD$3:$AR$9,AF$11,FALSE)) | AM25: =IF($A25="","",HLOOKUP($AI25,$AD$3:$AR$9,AG$11,FALSE)) | AN25: =IF($A25="","",HLOOKUP($AI25,$AD$3:$AR$9,AH$11,FALSE)) | AO25: =IF($A25="","",HLOOKUP($AI25,$AD$3:$AR$9,AI$11,FALSE)) | AP25: =SUM(AJ25:AO25) -> 0
A26: =IF(ISBLANK(CT!A41),"",CT!A41) | U26: =IF($A26="","",SUM(B26:T26)) | V26: =IF($A26="","",SUMIF($B$4:$T$4,">0",$B26:$T26)) | W26: =IF($A26="","",SUMIF($B$5:$T$5,">0",$B26:$T26)) | X26: =IF($A26="","",SUMIF($B$6:$T$6,">0",$B26:$T26)) | Y26: =IF($A26="","",SUMIF($B$7:$T$7,">0",$B26:$T26)) | Z26: =IF($A26="","",SUMIF($B$8:$T$8,">0",$B26:$T26)) | AA26: =IF($A26="","",SUMIF($B$9:$T$9,">0",$B26:$T26)) | AC26: =IF($A26="","",SUM(B26:E26)) | AD26: =IF($A26="","",SUM(G26:J26)) | AE26: =IF($A26="","",SUM(L26:O26)) | AF26: =IF($A26="","",SUM(Q26:T26)) | AG26: =COUNTIF(AC26:AF26,0) -> 0 | AH26: =IF(SUM(AC26:AF26)=0,"None",CONCATENATE(IF(AC26>0,AC$16&",",""),IF(AD26>0,AD$16&",",""),IF(AE26>0,AE$16&",",""),IF(AF26>0,AF$16,""))) -> None | AI26: =IF(AH26<>"",IF(RIGHT(AH26,1)=",",LEFT(AH26,LEN(AH26)-1),AH26),"None") -> None | AJ26: =IF($A26="","",HLOOKUP($AI26,$AD$3:$AR$9,AD$11,FALSE)) | AK26: =IF($A26="","",HLOOKUP($AI26,$AD$3:$AR$9,AE$11,FALSE)) | AL26: =IF($A26="","",HLOOKUP($AI26,$AD$3:$AR$9,AF$11,FALSE)) | AM26: =IF($A26="","",HLOOKUP($AI26,$AD$3:$AR$9,AG$11,FALSE)) | AN26: =IF($A26="","",HLOOKUP($AI26,$AD$3:$AR$9,AH$11,FALSE)) | AO26: =IF($A26="","",HLOOKUP($AI26,$AD$3:$AR$9,AI$11,FALSE)) | AP26: =SUM(AJ26:AO26) -> 0 | AT26: =AT15 -> 1,2 | AU26: =AU15 -> 1,3 | AV26: =AV15 -> 1,4 | AW26: =AW15 -> 2,3 | AX26: =AX15 -> 2,4 | AY26: =AY15 -> 3,4 | AZ26: =AZ15 -> 1 | BA26: =BA15 -> 2 | ... BD26: =BD15 -> None
A27: =IF(ISBLANK(CT!A42),"",CT!A42) | U27: =IF($A27="","",SUM(B27:T27)) | V27: =IF($A27="","",SUMIF($B$4:$T$4,">0",$B27:$T27)) | W27: =IF($A27="","",SUMIF($B$5:$T$5,">0",$B27:$T27)) | X27: =IF($A27="","",SUMIF($B$6:$T$6,">0",$B27:$T27)) | Y27: =IF($A27="","",SUMIF($B$7:$T$7,">0",$B27:$T27)) | Z27: =IF($A27="","",SUMIF($B$8:$T$8,">0",$B27:$T27)) | AA27: =IF($A27="","",SUMIF($B$9:$T$9,">0",$B27:$T27)) | AC27: =IF($A27="","",SUM(B27:E27)) | AD27: =IF($A27="","",SUM(G27:J27)) | AE27: =IF($A27="","",SUM(L27:O27)) | AF27: =IF($A27="","",SUM(Q27:T27)) | AG27: =COUNTIF(AC27:AF27,0) -> 0 | AH27: =IF(SUM(AC27:AF27)=0,"None",CONCATENATE(IF(AC27>0,AC$16&",",""),IF(AD27>0,AD$16&",",""),IF(AE27>0,AE$16&",",""),IF(AF27>0,AF$16,""))) -> None | AI27: =IF(AH27<>"",IF(RIGHT(AH27,1)=",",LEFT(AH27,LEN(AH27)-1),AH27),"None") -> None | AJ27: =IF($A27="","",HLOOKUP($AI27,$AD$3:$AR$9,AD$11,FALSE)) | AK27: =IF($A27="","",HLOOKUP($AI27,$AD$3:$AR$9,AE$11,FALSE)) | AL27: =IF($A27="","",HLOOKUP($AI27,$AD$3:$AR$9,AF$11,FALSE)) | AM27: =IF($A27="","",HLOOKUP($AI27,$AD$3:$AR$9,AG$11,FALSE)) | AN27: =IF($A27="","",HLOOKUP($AI27,$AD$3:$AR$9,AH$11,FALSE)) | AO27: =IF($A27="","",HLOOKUP($AI27,$AD$3:$AR$9,AI$11,FALSE)) | AP27: =SUM(AJ27:AO27) -> 0 | AR27: =AT15 -> 1,2 | AT27: =SUMXMY2($AT$16:$AT$21,AT16:AT21) -> #DIV/0! | AU27: =SUMXMY2($AT$16:$AT$21,AU16:AU21) -> #DIV/0! | AV27: =SUMXMY2($AT$16:$AT$21,AV16:AV21) -> #DIV/0! | AW27: =SUMXMY2($AT$16:$AT$21,AW16:AW21) -> #DIV/0! | AX27: =SUMXMY2($AT$16:$AT$21,AX16:AX21) -> #DIV/0! | AY27: =SUMXMY2($AT$16:$AT$21,AY16:AY21) -> #DIV/0! | AZ27: =SUMXMY2($AT$16:$AT$21,AZ16:AZ21) -> #DIV/0! | BA27: =SUMXMY2($AT$16:$AT$21,BA16:BA21) -> #DIV/0! | ... BC27: =SUMXMY2($AT$16:$AT$21,BC16:BC21) -> #DIV/0!
A28: =IF(ISBLANK(CT!A43),"",CT!A43) | U28: =IF($A28="","",SUM(B28:T28)) | V28: =IF($A28="","",SUMIF($B$4:$T$4,">0",$B28:$T28)) | W28: =IF($A28="","",SUMIF($B$5:$T$5,">0",$B28:$T28)) | X28: =IF($A28="","",SUMIF($B$6:$T$6,">0",$B28:$T28)) | Y28: =IF($A28="","",SUMIF($B$7:$T$7,">0",$B28:$T28)) | Z28: =IF($A28="","",SUMIF($B$8:$T$8,">0",$B28:$T28)) | AA28: =IF($A28="","",SUMIF($B$9:$T$9,">0",$B28:$T28)) | AC28: =IF($A28="","",SUM(B28:E28)) | AD28: =IF($A28="","",SUM(G28:J28)) | AE28: =IF($A28="","",SUM(L28:O28)) | AF28: =IF($A28="","",SUM(Q28:T28)) | AG28: =COUNTIF(AC28:AF28,0) -> 0 | AH28: =IF(SUM(AC28:AF28)=0,"None",CONCATENATE(IF(AC28>0,AC$16&",",""),IF(AD28>0,AD$16&",",""),IF(AE28>0,AE$16&",",""),IF(AF28>0,AF$16,""))) -> None | AI28: =IF(AH28<>"",IF(RIGHT(AH28,1)=",",LEFT(AH28,LEN(AH28)-1),AH28),"None") -> None | AJ28: =IF($A28="","",HLOOKUP($AI28,$AD$3:$AR$9,AD$11,FALSE)) | AK28: =IF($A28="","",HLOOKUP($AI28,$AD$3:$AR$9,AE$11,FALSE)) | AL28: =IF($A28="","",HLOOKUP($AI28,$AD$3:$AR$9,AF$11,FALSE)) | AM28: =IF($A28="","",HLOOKUP($AI28,$AD$3:$AR$9,AG$11,FALSE)) | AN28: =IF($A28="","",HLOOKUP($AI28,$AD$3:$AR$9,AH$11,FALSE)) | AO28: =IF($A28="","",HLOOKUP($AI28,$AD$3:$AR$9,AI$11,FALSE)) | AP28: =SUM(AJ28:AO28) -> 0 | AR28: =AU15 -> 1,3 | AT28: =SUMXMY2($AU$16:$AU$21,AT$16:AT$21) -> #DIV/0! | AU28: =SUMXMY2($AU$16:$AU$21,AU$16:AU$21) -> #DIV/0! | AV28: =SUMXMY2($AU$16:$AU$21,AV$16:AV$21) -> #DIV/0! | AW28: =SUMXMY2($AU$16:$AU$21,AW$16:AW$21) -> #DIV/0! | AX28: =SUMXMY2($AU$16:$AU$21,AX$16:AX$21) -> #DIV/0! | AY28: =SUMXMY2($AU$16:$AU$21,AY$16:AY$21) -> #DIV/0! | AZ28: =SUMXMY2($AU$16:$AU$21,AZ$16:AZ$21) -> #DIV/0! | BA28: =SUMXMY2($AU$16:$AU$21,BA$16:BA$21) -> #DIV/0! | ... BC28: =SUMXMY2($AU$16:$AU$21,BC$16:BC$21) -> #DIV/0!
